Workbook

Sheet Live_Input
A1: ⚾ SIGNAL-INTERCEPT | Live Data Collection Engine
A2: INNING | B2: OUTS | C2: COUNT | D2: SCORE | E2: R on 2nd? | F2: CHEST WIPE | G2: TOUCH MASK | H2: GLOVE TAP | I2: SHIFT SETUP | J2: SIGN RESET? | K2: RAW SIGN STRING (e.g. 2-4-1-3-1) | L2: PITCH RESULT | M2: SIGN 1 | N2: SIGN 2 | O2: SIGN 3 | P2: SIGN 4 | Q2: SIGN 5 | R2: SIGN 6 | S2: SIGN 7 | T2: LAST SIGN | U2: SEQ LEN | V2: SHAKE COUNT | W2: SHAKE-ADJ SIGN | X2: THEORY PREDICTED | Y2: CORRECT?
A3: 1 | B3: 0 | E3: =FALSE() -> FALSE | F3: =FALSE() -> FALSE | G3: =FALSE() -> FALSE | H3: =FALSE() -> FALSE | I3: =FALSE() -> FALSE | J3: =FALSE() -> FALSE | M3: =IFERROR(VALUE(TRIM(MID(SUBSTITUTE(K3,"-",REPT(" ",100)),(1-1)*100+1,100))),"") | N3: =IFERROR(VALUE(TRIM(MID(SUBSTITUTE(K3,"-",REPT(" ",100)),(2-1)*100+1,100))),"") | O3: =IFERROR(VALUE(TRIM(MID(SUBSTITUTE(K3,"-",REPT(" ",100)),(3-1)*100+1,100))),"") | P3: =IFERROR(VALUE(TRIM(MID(SUBSTITUTE(K3,"-",REPT(" ",100)),(4-1)*100+1,100))),"") | Q3: =IFERROR(VALUE(TRIM(MID(SUBSTITUTE(K3,"-",REPT(" ",100)),(5-1)*100+1,100))),"") | R3: =IFERROR(VALUE(TRIM(MID(SUBSTITUTE(K3,"-",REPT(" ",100)),(6-1)*100+1,100))),"") | S3: =IFERROR(VALUE(TRIM(MID(SUBSTITUTE(K3,"-",REPT(" ",100)),(7-1)*100+1,100))),"") | T3: =IFERROR(LOOKUP(2,1/(M3:S3<>""),M3:S3),"") | U3: =IF(K3="","",LEN(K3)-LEN(SUBSTITUTE(K3,"-",""))+1) | V3: 0 | W3: =IFERROR(IF(V3=0,T3,IFERROR(VALUE(TRIM(MID(SUBSTITUTE(K3,"-",REPT(" ",100)),(U3-V3-1)*100+1,100))),"")),"") | X3: =IFERROR(RealTime_Prediction!B4,"") -> ⚠ No confident prediction | Y3: =IF(AND(X3<>"",L3<>""),IF(X3=L3,"✓ YES","✗ NO"),"")
A4: 1 | B4: 0 | E4: =FALSE() -> FALSE | F4: =FALSE() -> FALSE | G4: =FALSE() -> FALSE | H4: =FALSE() -> FALSE | I4: =FALSE() -> FALSE | J4: =FALSE() -> FALSE | M4: =IFERROR(VALUE(TRIM(MID(SUBSTITUTE(K4,"-",REPT(" ",100)),(1-1)*100+1,100))),"") | N4: =IFERROR(VALUE(TRIM(MID(SUBSTITUTE(K4,"-",REPT(" ",100)),(2-1)*100+1,100))),"") | O4: =IFERROR(VALUE(TRIM(MID(SUBSTITUTE(K4,"-",REPT(" ",100)),(3-1)*100+1,100))),"") | P4: =IFERROR(VALUE(TRIM(MID(SUBSTITUTE(K4,"-",REPT(" ",100)),(4-1)*100+1,100))),"") | Q4: =IFERROR(VALUE(TRIM(MID(SUBSTITUTE(K4,"-",REPT(" ",100)),(5-1)*100+1,100))),"") | R4: =IFERROR(VALUE(TRIM(MID(SUBSTITUTE(K4,"-",REPT(" ",100)),(6-1)*100+1,100))),"") | S4: =IFERROR(VALUE(TRIM(MID(SUBSTITUTE(K4,"-",REPT(" ",100)),(7-1)*100+1,100))),"") | T4: =IFERROR(LOOKUP(2,1/(M4:S4<>""),M4:S4),"") | U4: =IF(K4="","",LEN(K4)-LEN(SUBSTITUTE(K4,"-",""))+1) | V4: 0 | W4: =IFERROR(IF(V4=0,T4,IFERROR(VALUE(TRIM(MID(SUBSTITUTE(K4,"-",REPT(" ",100)),(U4-V4-1)*100+1,100))),"")),"") | X4: =IFERROR(RealTime_Prediction!B4,"") -> ⚠ No confident prediction | Y4: =IF(AND(X4<>"",L4<>""),IF(X4=L4,"✓ YES","✗ NO"),"")
A5: 1 | B5: 1 | E5: =FALSE() -> FALSE | F5: =FALSE() -> FALSE | G5: =FALSE() -> FALSE | H5: =FALSE() -> FALSE | I5: =FALSE() -> FALSE | J5: =FALSE() -> FALSE | M5: =IFERROR(VALUE(TRIM(MID(SUBSTITUTE(K5,"-",REPT(" ",100)),(1-1)*100+1,100))),"") | N5: =IFERROR(VALUE(TRIM(MID(SUBSTITUTE(K5,"-",REPT(" ",100)),(2-1)*100+1,100))),"") | O5: =IFERROR(VALUE(TRIM(MID(SUBSTITUTE(K5,"-",REPT(" ",100)),(3-1)*100+1,100))),"") | P5: =IFERROR(VALUE(TRIM(MID(SUBSTITUTE(K5,"-",REPT(" ",100)),(4-1)*100+1,100))),"") | Q5: =IFERROR(VALUE(TRIM(MID(SUBSTITUTE(K5,"-",REPT(" ",100)),(5-1)*100+1,100))),"") | R5: =IFERROR(VALUE(TRIM(MID(SUBSTITUTE(K5,"-",REPT(" ",100)),(6-1)*100+1,100))),"") | S5: =IFERROR(VALUE(TRIM(MID(SUBSTITUTE(K5,"-",REPT(" ",100)),(7-1)*100+1,100))),"") | T5: =IFERROR(LOOKUP(2,1/(M5:S5<>""),M5:S5),"") | U5: =IF(K5="","",LEN(K5)-LEN(SUBSTITUTE(K5,"-",""))+1) | V5: 0 | W5: =IFERROR(IF(V5=0,T5,IFERROR(VALUE(TRIM(MID(SUBSTITUTE(K5,"-",REPT(" ",100)),(U5-V5-1)*100+1,100))),"")),"") | X5: =IFERROR(RealTime_Prediction!B4,"") -> ⚠ No confident prediction | Y5: =IF(AND(X5<>"",L5<>""),IF(X5=L5,"✓ YES","✗ NO"),"")
A6: 1 | B6: 1 | E6: =FALSE() -> FALSE | F6: =FALSE() -> FALSE | G6: =FALSE() -> FALSE | H6: =FALSE() -> FALSE | I6: =FALSE() -> FALSE | J6: =FALSE() -> FALSE | M6: =IFERROR(VALUE(TRIM(MID(SUBSTITUTE(K6,"-",REPT(" ",100)),(1-1)*100+1,100))),"") | N6: =IFERROR(VALUE(TRIM(MID(SUBSTITUTE(K6,"-",REPT(" ",100)),(2-1)*100+1,100))),"") | O6: =IFERROR(VALUE(TRIM(MID(SUBSTITUTE(K6,"-",REPT(" ",100)),(3-1)*100+1,100))),"") | P6: =IFERROR(VALUE(TRIM(MID(SUBSTITUTE(K6,"-",REPT(" ",100)),(4-1)*100+1,100))),"") | Q6: =IFERROR(VALUE(TRIM(MID(SUBSTITUTE(K6,"-",REPT(" ",100)),(5-1)*100+1,100))),"") | R6: =IFERROR(VALUE(TRIM(MID(SUBSTITUTE(K6,"-",REPT(" ",100)),(6-1)*100+1,100))),"") | S6: =IFERROR(VALUE(TRIM(MID(SUBSTITUTE(K6,"-",REPT(" ",100)),(7-1)*100+1,100))),"") | T6: =IFERROR(LOOKUP(2,1/(M6:S6<>""),M6:S6),"") | U6: =IF(K6="","",LEN(K6)-LEN(SUBSTITUTE(K6,"-",""))+1) | V6: 0 | W6: =IFERROR(IF(V6=0,T6,IFERROR(VALUE(TRIM(MID(SUBSTITUTE(K6,"-",REPT(" ",100)),(U6-V6-1)*100+1,100))),"")),"") | X6: =IFERROR(RealTime_Prediction!B4,"") -> ⚠ No confident prediction | Y6: =IF(AND(X6<>"",L6<>""),IF(X6=L6,"✓ YES","✗ NO"),"")
A7: 1 | B7: 1 | E7: =FALSE() -> FALSE | F7: =FALSE() -> FALSE | G7: =FALSE() -> FALSE | H7: =FALSE() -> FALSE | I7: =FALSE() -> FALSE | J7: =FALSE() -> FALSE | M7: =IFERROR(VALUE(TRIM(MID(SUBSTITUTE(K7,"-",REPT(" ",100)),(1-1)*100+1,100))),"") | N7: =IFERROR(VALUE(TRIM(MID(SUBSTITUTE(K7,"-",REPT(" ",100)),(2-1)*100+1,100))),"") | O7: =IFERROR(VALUE(TRIM(MID(SUBSTITUTE(K7,"-",REPT(" ",100)),(3-1)*100+1,100))),"") | P7: =IFERROR(VALUE(TRIM(MID(SUBSTITUTE(K7,"-",REPT(" ",100)),(4-1)*100+1,100))),"") | Q7: =IFERROR(VALUE(TRIM(MID(SUBSTITUTE(K7,"-",REPT(" ",100)),(5-1)*100+1,100))),"") | R7: =IFERROR(VALUE(TRIM(MID(SUBSTITUTE(K7,"-",REPT(" ",100)),(6-1)*100+1,100))),"") | S7: =IFERROR(VALUE(TRIM(MID(SUBSTITUTE(K7,"-",REPT(" ",100)),(7-1)*100+1,100))),"") | T7: =IFERROR(LOOKUP(2,1/(M7:S7<>""),M7:S7),"") | U7: =IF(K7="","",LEN(K7)-LEN(SUBSTITUTE(K7,"-",""))+1) | V7: 0 | W7: =IFERROR(IF(V7=0,T7,IFERROR(VALUE(TRIM(MID(SUBSTITUTE(K7,"-",REPT(" ",100)),(U7-V7-1)*100+1,100))),"")),"") | X7: =IFERROR(RealTime_Prediction!B4,"") -> ⚠ No confident prediction | Y7: =IF(AND(X7<>"",L7<>""),IF(X7=L7,"✓ YES","✗ NO"),"")
E8: =FALSE() -> FALSE | F8: =FALSE() -> FALSE | G8: =FALSE() -> FALSE | H8: =FALSE() -> FALSE | I8: =FALSE() -> FALSE | J8: =FALSE() -> FALSE | M8: =IFERROR(VALUE(TRIM(MID(SUBSTITUTE(K8,"-",REPT(" ",100)),(1-1)*100+1,100))),"") | N8: =IFERROR(VALUE(TRIM(MID(SUBSTITUTE(K8,"-",REPT(" ",100)),(2-1)*100+1,100))),"") | O8: =IFERROR(VALUE(TRIM(MID(SUBSTITUTE(K8,"-",REPT(" ",100)),(3-1)*100+1,100))),"") | P8: =IFERROR(VALUE(TRIM(MID(SUBSTITUTE(K8,"-",REPT(" ",100)),(4-1)*100+1,100))),"") | Q8: =IFERROR(VALUE(TRIM(MID(SUBSTITUTE(K8,"-",REPT(" ",100)),(5-1)*100+1,100))),"") | R8: =IFERROR(VALUE(TRIM(MID(SUBSTITUTE(K8,"-",REPT(" ",100)),(6-1)*100+1,100))),"") | S8: =IFERROR(VALUE(TRIM(MID(SUBSTITUTE(K8,"-",REPT(" ",100)),(7-1)*100+1,100))),"") | T8: =IFERROR(LOOKUP(2,1/(M8:S8<>""),M8:S8),"") | U8: =IF(K8="","",LEN(K8)-LEN(SUBSTITUTE(K8,"-",""))+1) | V8: 0 | W8: =IFERROR(IF(V8=0,T8,IFERROR(VALUE(TRIM(MID(SUBSTITUTE(K8,"-",REPT(" ",100)),(U8-V8-1)*100+1,100))),"")),"") | X8: =IFERROR(RealTime_Prediction!B4,"") -> ⚠ No confident prediction | Y8: =IF(AND(X8<>"",L8<>""),IF(X8=L8,"✓ YES","✗ NO"),"")
E9: =FALSE() -> FALSE | F9: =FALSE() -> FALSE | G9: =FALSE() -> FALSE | H9: =FALSE() -> FALSE | I9: =FALSE() -> FALSE | J9: =FALSE() -> FALSE | M9: =IFERROR(VALUE(TRIM(MID(SUBSTITUTE(K9,"-",REPT(" ",100)),(1-1)*100+1,100))),"") | N9: =IFERROR(VALUE(TRIM(MID(SUBSTITUTE(K9,"-",REPT(" ",100)),(2-1)*100+1,100))),"") | O9: =IFERROR(VALUE(TRIM(MID(SUBSTITUTE(K9,"-",REPT(" ",100)),(3-1)*100+1,100))),"") | P9: =IFERROR(VALUE(TRIM(MID(SUBSTITUTE(K9,"-",REPT(" ",100)),(4-1)*100+1,100))),"") | Q9: =IFERROR(VALUE(TRIM(MID(SUBSTITUTE(K9,"-",REPT(" ",100)),(5-1)*100+1,100))),"") | R9: =IFERROR(VALUE(TRIM(MID(SUBSTITUTE(K9,"-",REPT(" ",100)),(6-1)*100+1,100))),"") | S9: =IFERROR(VALUE(TRIM(MID(SUBSTITUTE(K9,"-",REPT(" ",100)),(7-1)*100+1,100))),"") | T9: =IFERROR(LOOKUP(2,1/(M9:S9<>""),M9:S9),"") | U9: =IF(K9="","",LEN(K9)-LEN(SUBSTITUTE(K9,"-",""))+1) | V9: 0 | W9: =IFERROR(IF(V9=0,T9,IFERROR(VALUE(TRIM(MID(SUBSTITUTE(K9,"-",REPT(" ",100)),(U9-V9-1)*100+1,100))),"")),"") | X9: =IFERROR(RealTime_Prediction!B4,"") -> ⚠ No confident prediction | Y9: =IF(AND(X9<>"",L9<>""),IF(X9=L9,"✓ YES","✗ NO"),"")
E10: =FALSE() -> FALSE | F10: =FALSE() -> FALSE | G10: =FALSE() -> FALSE | H10: =FALSE() -> FALSE | I10: =FALSE() -> FALSE | J10: =FALSE() -> FALSE | M10: =IFERROR(VALUE(TRIM(MID(SUBSTITUTE(K10,"-",REPT(" ",100)),(1-1)*100+1,100))),"") | N10: =IFERROR(VALUE(TRIM(MID(SUBSTITUTE(K10,"-",REPT(" ",100)),(2-1)*100+1,100))),"") | O10: =IFERROR(VALUE(TRIM(MID(SUBSTITUTE(K10,"-",REPT(" ",100)),(3-1)*100+1,100))),"") | P10: =IFERROR(VALUE(TRIM(MID(SUBSTITUTE(K10,"-",REPT(" ",100)),(4-1)*100+1,100))),"") | Q10: =IFERROR(VALUE(TRIM(MID(SUBSTITUTE(K10,"-",REPT(" ",100)),(5-1)*100+1,100))),"") | R10: =IFERROR(VALUE(TRIM(MID(SUBSTITUTE(K10,"-",REPT(" ",100)),(6-1)*100+1,100))),"") | S10: =IFERROR(VALUE(TRIM(MID(SUBSTITUTE(K10,"-",REPT(" ",100)),(7-1)*100+1,100))),"") | T10: =IFERROR(LOOKUP(2,1/(M10:S10<>""),M10:S10),"") | U10: =IF(K10="","",LEN(K10)-LEN(SUBSTITUTE(K10,"-",""))+1) | V10: 0 | W10: =IFERROR(IF(V10=0,T10,IFERROR(VALUE(TRIM(MID(SUBSTITUTE(K10,"-",REPT(" ",100)),(U10-V10-1)*100+1,100))),"")),"") | X10: =IFERROR(RealTime_Prediction!B4,"") -> ⚠ No confident prediction | Y10: =IF(AND(X10<>"",L10<>""),IF(X10=L10,"✓ YES","✗ NO"),"")
E11: =FALSE() -> FALSE | F11: =FALSE() -> FALSE | G11: =FALSE() -> FALSE | H11: =FALSE() -> FALSE | I11: =FALSE() -> FALSE | J11: =FALSE() -> FALSE | M11: =IFERROR(VALUE(TRIM(MID(SUBSTITUTE(K11,"-",REPT(" ",100)),(1-1)*100+1,100))),"") | N11: =IFERROR(VALUE(TRIM(MID(SUBSTITUTE(K11,"-",REPT(" ",100)),(2-1)*100+1,100))),"") | O11: =IFERROR(VALUE(TRIM(MID(SUBSTITUTE(K11,"-",REPT(" ",100)),(3-1)*100+1,100))),"") | P11: =IFERROR(VALUE(TRIM(MID(SUBSTITUTE(K11,"-",REPT(" ",100)),(4-1)*100+1,100))),"") | Q11: =IFERROR(VALUE(TRIM(MID(SUBSTITUTE(K11,"-",REPT(" ",100)),(5-1)*100+1,100))),"") | R11: =IFERROR(VALUE(TRIM(MID(SUBSTITUTE(K11,"-",REPT(" ",100)),(6-1)*100+1,100))),"") | S11: =IFERROR(VALUE(TRIM(MID(SUBSTITUTE(K11,"-",REPT(" ",100)),(7-1)*100+1,100))),"") | T11: =IFERROR(LOOKUP(2,1/(M11:S11<>""),M11:S11),"") | U11: =IF(K11="","",LEN(K11)-LEN(SUBSTITUTE(K11,"-",""))+1) | V11: 0 | W11: =IFERROR(IF(V11=0,T11,IFERROR(VALUE(TRIM(MID(SUBSTITUTE(K11,"-",REPT(" ",100)),(U11-V11-1)*100+1,100))),"")),"") | X11: =IFERROR(RealTime_Prediction!B4,"") -> ⚠ No confident prediction | Y11: =IF(AND(X11<>"",L11<>""),IF(X11=L11,"✓ YES","✗ NO"),"")
E12: =FALSE() -> FALSE | F12: =FALSE() -> FALSE | G12: =FALSE() -> FALSE | H12: =FALSE() -> FALSE | I12: =FALSE() -> FALSE | J12: =FALSE() -> FALSE | M12: =IFERROR(VALUE(TRIM(MID(SUBSTITUTE(K12,"-",REPT(" ",100)),(1-1)*100+1,100))),"") | N12: =IFERROR(VALUE(TRIM(MID(SUBSTITUTE(K12,"-",REPT(" ",100)),(2-1)*100+1,100))),"") | O12: =IFERROR(VALUE(TRIM(MID(SUBSTITUTE(K12,"-",REPT(" ",100)),(3-1)*100+1,100))),"") | P12: =IFERROR(VALUE(TRIM(MID(SUBSTITUTE(K12,"-",REPT(" ",100)),(4-1)*100+1,100))),"") | Q12: =IFERROR(VALUE(TRIM(MID(SUBSTITUTE(K12,"-",REPT(" ",100)),(5-1)*100+1,100))),"") | R12: =IFERROR(VALUE(TRIM(MID(SUBSTITUTE(K12,"-",REPT(" ",100)),(6-1)*100+1,100))),"") | S12: =IFERROR(VALUE(TRIM(MID(SUBSTITUTE(K12,"-",REPT(" ",100)),(7-1)*100+1,100))),"") | T12: =IFERROR(LOOKUP(2,1/(M12:S12<>""),M12:S12),"") | U12: =IF(K12="","",LEN(K12)-LEN(SUBSTITUTE(K12,"-",""))+1) | V12: 0 | W12: =IFERROR(IF(V12=0,T12,IFERROR(VALUE(TRIM(MID(SUBSTITUTE(K12,"-",REPT(" ",100)),(U12-V12-1)*100+1,100))),"")),"") | X12: =IFERROR(RealTime_Prediction!B4,"") -> ⚠ No confident prediction | Y12: =IF(AND(X12<>"",L12<>""),IF(X12=L12,"✓ YES","✗ NO"),"")
E13: =FALSE() -> FALSE | F13: =FALSE() -> FALSE | G13: =FALSE() -> FALSE | H13: =FALSE() -> FALSE | I13: =FALSE() -> FALSE | J13: =FALSE() -> FALSE | M13: =IFERROR(VALUE(TRIM(MID(SUBSTITUTE(K13,"-",REPT(" ",100)),(1-1)*100+1,100))),"") | N13: =IFERROR(VALUE(TRIM(MID(SUBSTITUTE(K13,"-",REPT(" ",100)),(2-1)*100+1,100))),"") | O13: =IFERROR(VALUE(TRIM(MID(SUBSTITUTE(K13,"-",REPT(" ",100)),(3-1)*100+1,100))),"") | P13: =IFERROR(VALUE(TRIM(MID(SUBSTITUTE(K13,"-",REPT(" ",100)),(4-1)*100+1,100))),"") | Q13: =IFERROR(VALUE(TRIM(MID(SUBSTITUTE(K13,"-",REPT(" ",100)),(5-1)*100+1,100))),"") | R13: =IFERROR(VALUE(TRIM(MID(SUBSTITUTE(K13,"-",REPT(" ",100)),(6-1)*100+1,100))),"") | S13: =IFERROR(VALUE(TRIM(MID(SUBSTITUTE(K13,"-",REPT(" ",100)),(7-1)*100+1,100))),"") | T13: =IFERROR(LOOKUP(2,1/(M13:S13<>""),M13:S13),"") | U13: =IF(K13="","",LEN(K13)-LEN(SUBSTITUTE(K13,"-",""))+1) | V13: 0 | W13: =IFERROR(IF(V13=0,T13,IFERROR(VALUE(TRIM(MID(SUBSTITUTE(K13,"-",REPT(" ",100)),(U13-V13-1)*100+1,100))),"")),"") | X13: =IFERROR(RealTime_Prediction!B4,"") -> ⚠ No confident prediction | Y13: =IF(AND(X13<>"",L13<>""),IF(X13=L13,"✓ YES","✗ NO"),"")
E14: =FALSE() -> FALSE | F14: =FALSE() -> FALSE | G14: =FALSE() -> FALSE | H14: =FALSE() -> FALSE | I14: =FALSE() -> FALSE | J14: =FALSE() -> FALSE | M14: =IFERROR(VALUE(TRIM(MID(SUBSTITUTE(K14,"-",REPT(" ",100)),(1-1)*100+1,100))),"") | N14: =IFERROR(VALUE(TRIM(MID(SUBSTITUTE(K14,"-",REPT(" ",100)),(2-1)*100+1,100))),"") | O14: =IFERROR(VALUE(TRIM(MID(SUBSTITUTE(K14,"-",REPT(" ",100)),(3-1)*100+1,100))),"") | P14: =IFERROR(VALUE(TRIM(MID(SUBSTITUTE(K14,"-",REPT(" ",100)),(4-1)*100+1,100))),"") | Q14: =IFERROR(VALUE(TRIM(MID(SUBSTITUTE(K14,"-",REPT(" ",100)),(5-1)*100+1,100))),"") | R14: =IFERROR(VALUE(TRIM(MID(SUBSTITUTE(K14,"-",REPT(" ",100)),(6-1)*100+1,100))),"") | S14: =IFERROR(VALUE(TRIM(MID(SUBSTITUTE(K14,"-",REPT(" ",100)),(7-1)*100+1,100))),"") | T14: =IFERROR(LOOKUP(2,1/(M14:S14<>""),M14:S14),"") | U14: =IF(K14="","",LEN(K14)-LEN(SUBSTITUTE(K14,"-",""))+1) | V14: 0 | W14: =IFERROR(IF(V14=0,T14,IFERROR(VALUE(TRIM(MID(SUBSTITUTE(K14,"-",REPT(" ",100)),(U14-V14-1)*100+1,100))),"")),"") | X14: =IFERROR(RealTime_Prediction!B4,"") -> ⚠ No confident prediction | Y14: =IF(AND(X14<>"",L14<>""),IF(X14=L14,"✓ YES","✗ NO"),"")
E15: =FALSE() -> FALSE | F15: =FALSE() -> FALSE | G15: =FALSE() -> FALSE | H15: =FALSE() -> FALSE | I15: =FALSE() -> FALSE | J15: =FALSE() -> FALSE | M15: =IFERROR(VALUE(TRIM(MID(SUBSTITUTE(K15,"-",REPT(" ",100)),(1-1)*100+1,100))),"") | N15: =IFERROR(VALUE(TRIM(MID(SUBSTITUTE(K15,"-",REPT(" ",100)),(2-1)*100+1,100))),"") | O15: =IFERROR(VALUE(TRIM(MID(SUBSTITUTE(K15,"-",REPT(" ",100)),(3-1)*100+1,100))),"") | P15: =IFERROR(VALUE(TRIM(MID(SUBSTITUTE(K15,"-",REPT(" ",100)),(4-1)*100+1,100))),"") | Q15: =IFERROR(VALUE(TRIM(MID(SUBSTITUTE(K15,"-",REPT(" ",100)),(5-1)*100+1,100))),"") | R15: =IFERROR(VALUE(TRIM(MID(SUBSTITUTE(K15,"-",REPT(" ",100)),(6-1)*100+1,100))),"") | S15: =IFERROR(VALUE(TRIM(MID(SUBSTITUTE(K15,"-",REPT(" ",100)),(7-1)*100+1,100))),"") | T15: =IFERROR(LOOKUP(2,1/(M15:S15<>""),M15:S15),"") | U15: =IF(K15="","",LEN(K15)-LEN(SUBSTITUTE(K15,"-",""))+1) | V15: 0 | W15: =IFERROR(IF(V15=0,T15,IFERROR(VALUE(TRIM(MID(SUBSTITUTE(K15,"-",REPT(" ",100)),(U15-V15-1)*100+1,100))),"")),"") | X15: =IFERROR(RealTime_Prediction!B4,"") -> ⚠ No confident prediction | Y15: =IF(AND(X15<>"",L15<>""),IF(X15=L15,"✓ YES","✗ NO"),"")
E16: =FALSE() -> FALSE | F16: =FALSE() -> FALSE | G16: =FALSE() -> FALSE | H16: =FALSE() -> FALSE | I16: =FALSE() -> FALSE | J16: =FALSE() -> FALSE | M16: =IFERROR(VALUE(TRIM(MID(SUBSTITUTE(K16,"-",REPT(" ",100)),(1-1)*100+1,100))),"") | N16: =IFERROR(VALUE(TRIM(MID(SUBSTITUTE(K16,"-",REPT(" ",100)),(2-1)*100+1,100))),"") | O16: =IFERROR(VALUE(TRIM(MID(SUBSTITUTE(K16,"-",REPT(" ",100)),(3-1)*100+1,100))),"") | P16: =IFERROR(VALUE(TRIM(MID(SUBSTITUTE(K16,"-",REPT(" ",100)),(4-1)*100+1,100))),"") | Q16: =IFERROR(VALUE(TRIM(MID(SUBSTITUTE(K16,"-",REPT(" ",100)),(5-1)*100+1,100))),"") | R16: =IFERROR(VALUE(TRIM(MID(SUBSTITUTE(K16,"-",REPT(" ",100)),(6-1)*100+1,100))),"") | S16: =IFERROR(VALUE(TRIM(MID(SUBSTITUTE(K16,"-",REPT(" ",100)),(7-1)*100+1,100))),"") | T16: =IFERROR(LOOKUP(2,1/(M16:S16<>""),M16:S16),"") | U16: =IF(K16="","",LEN(K16)-LEN(SUBSTITUTE(K16,"-",""))+1) | V16: 0 | W16: =IFERROR(IF(V16=0,T16,IFERROR(VALUE(TRIM(MID(SUBSTITUTE(K16,"-",REPT(" ",100)),(U16-V16-1)*100+1,100))),"")),"") | X16: =IFERROR(RealTime_Prediction!B4,"") -> ⚠ No confident prediction | Y16: =IF(AND(X16<>"",L16<>""),IF(X16=L16,"✓ YES","✗ NO"),"")
E17: =FALSE() -> FALSE | F17: =FALSE() -> FALSE | G17: =FALSE() -> FALSE | H17: =FALSE() -> FALSE | I17: =FALSE() -> FALSE | J17: =FALSE() -> FALSE | M17: =IFERROR(VALUE(TRIM(MID(SUBSTITUTE(K17,"-",REPT(" ",100)),(1-1)*100+1,100))),"") | N17: =IFERROR(VALUE(TRIM(MID(SUBSTITUTE(K17,"-",REPT(" ",100)),(2-1)*100+1,100))),"") | O17: =IFERROR(VALUE(TRIM(MID(SUBSTITUTE(K17,"-",REPT(" ",100)),(3-1)*100+1,100))),"") | P17: =IFERROR(VALUE(TRIM(MID(SUBSTITUTE(K17,"-",REPT(" ",100)),(4-1)*100+1,100))),"") | Q17: =IFERROR(VALUE(TRIM(MID(SUBSTITUTE(K17,"-",REPT(" ",100)),(5-1)*100+1,100))),"") | R17: =IFERROR(VALUE(TRIM(MID(SUBSTITUTE(K17,"-",REPT(" ",100)),(6-1)*100+1,100))),"") | S17: =IFERROR(VALUE(TRIM(MID(SUBSTITUTE(K17,"-",REPT(" ",100)),(7-1)*100+1,100))),"") | T17: =IFERROR(LOOKUP(2,1/(M17:S17<>""),M17:S17),"") | U17: =IF(K17="","",LEN(K17)-LEN(SUBSTITUTE(K17,"-",""))+1) | V17: 0 | W17: =IFERROR(IF(V17=0,T17,IFERROR(VALUE(TRIM(MID(SUBSTITUTE(K17,"-",REPT(" ",100)),(U17-V17-1)*100+1,100))),"")),"") | X17: =IFERROR(RealTime_Prediction!B4,"") -> ⚠ No confident prediction | Y17: =IF(AND(X17<>"",L17<>""),IF(X17=L17,"✓ YES","✗ NO"),"")
E18: =FALSE() -> FALSE | F18: =FALSE() -> FALSE | G18: =FALSE() -> FALSE | H18: =FALSE() -> FALSE | I18: =FALSE() -> FALSE | J18: =FALSE() -> FALSE | M18: =IFERROR(VALUE(TRIM(MID(SUBSTITUTE(K18,"-",REPT(" ",100)),(1-1)*100+1,100))),"") | N18: =IFERROR(VALUE(TRIM(MID(SUBSTITUTE(K18,"-",REPT(" ",100)),(2-1)*100+1,100))),"") | O18: =IFERROR(VALUE(TRIM(MID(SUBSTITUTE(K18,"-",REPT(" ",100)),(3-1)*100+1,100))),"") | P18: =IFERROR(VALUE(TRIM(MID(SUBSTITUTE(K18,"-",REPT(" ",100)),(4-1)*100+1,100))),"") | Q18: =IFERROR(VALUE(TRIM(MID(SUBSTITUTE(K18,"-",REPT(" ",100)),(5-1)*100+1,100))),"") | R18: =IFERROR(VALUE(TRIM(MID(SUBSTITUTE(K18,"-",REPT(" ",100)),(6-1)*100+1,100))),"") | S18: =IFERROR(VALUE(TRIM(MID(SUBSTITUTE(K18,"-",REPT(" ",100)),(7-1)*100+1,100))),"") | T18: =IFERROR(LOOKUP(2,1/(M18:S18<>""),M18:S18),"") | U18: =IF(K18="","",LEN(K18)-LEN(SUBSTITUTE(K18,"-",""))+1) | V18: 0 | W18: =IFERROR(IF(V18=0,T18,IFERROR(VALUE(TRIM(MID(SUBSTITUTE(K18,"-",REPT(" ",100)),(U18-V18-1)*100+1,100))),"")),"") | X18: =IFERROR(RealTime_Prediction!B4,"") -> ⚠ No confident prediction | Y18: =IF(AND(X18<>"",L18<>""),IF(X18=L18,"✓ YES","✗ NO"),"")
E19: =FALSE() -> FALSE | F19: =FALSE() -> FALSE | G19: =FALSE() -> FALSE | H19: =FALSE() -> FALSE | I19: =FALSE() -> FALSE | J19: =FALSE() -> FALSE | M19: =IFERROR(VALUE(TRIM(MID(SUBSTITUTE(K19,"-",REPT(" ",100)),(1-1)*100+1,100))),"") | N19: =IFERROR(VALUE(TRIM(MID(SUBSTITUTE(K19,"-",REPT(" ",100)),(2-1)*100+1,100))),"") | O19: =IFERROR(VALUE(TRIM(MID(SUBSTITUTE(K19,"-",REPT(" ",100)),(3-1)*100+1,100))),"") | P19: =IFERROR(VALUE(TRIM(MID(SUBSTITUTE(K19,"-",REPT(" ",100)),(4-1)*100+1,100))),"") | Q19: =IFERROR(VALUE(TRIM(MID(SUBSTITUTE(K19,"-",REPT(" ",100)),(5-1)*100+1,100))),"") | R19: =IFERROR(VALUE(TRIM(MID(SUBSTITUTE(K19,"-",REPT(" ",100)),(6-1)*100+1,100))),"") | S19: =IFERROR(VALUE(TRIM(MID(SUBSTITUTE(K19,"-",REPT(" ",100)),(7-1)*100+1,100))),"") | T19: =IFERROR(LOOKUP(2,1/(M19:S19<>""),M19:S19),"") | U19: =IF(K19="","",LEN(K19)-LEN(SUBSTITUTE(K19,"-",""))+1) | V19: 0 | W19: =IFERROR(IF(V19=0,T19,IFERROR(VALUE(TRIM(MID(SUBSTITUTE(K19,"-",REPT(" ",100)),(U19-V19-1)*100+1,100))),"")),"") | X19: =IFERROR(RealTime_Prediction!B4,"") -> ⚠ No confident prediction | Y19: =IF(AND(X19<>"",L19<>""),IF(X19=L19,"✓ YES","✗ NO"),"")
E20: =FALSE() -> FALSE | F20: =FALSE() -> FALSE | G20: =FALSE() -> FALSE | H20: =FALSE() -> FALSE | I20: =FALSE() -> FALSE | J20: =FALSE() -> FALSE | M20: =IFERROR(VALUE(TRIM(MID(SUBSTITUTE(K20,"-",REPT(" ",100)),(1-1)*100+1,100))),"") | N20: =IFERROR(VALUE(TRIM(MID(SUBSTITUTE(K20,"-",REPT(" ",100)),(2-1)*100+1,100))),"") | O20: =IFERROR(VALUE(TRIM(MID(SUBSTITUTE(K20,"-",REPT(" ",100)),(3-1)*100+1,100))),"") | P20: =IFERROR(VALUE(TRIM(MID(SUBSTITUTE(K20,"-",REPT(" ",100)),(4-1)*100+1,100))),"") | Q20: =IFERROR(VALUE(TRIM(MID(SUBSTITUTE(K20,"-",REPT(" ",100)),(5-1)*100+1,100))),"") | R20: =IFERROR(VALUE(TRIM(MID(SUBSTITUTE(K20,"-",REPT(" ",100)),(6-1)*100+1,100))),"") | S20: =IFERROR(VALUE(TRIM(MID(SUBSTITUTE(K20,"-",REPT(" ",100)),(7-1)*100+1,100))),"") | T20: =IFERROR(LOOKUP(2,1/(M20:S20<>""),M20:S20),"") | U20: =IF(K20="","",LEN(K20)-LEN(SUBSTITUTE(K20,"-",""))+1) | V20: 0 | W20: =IFERROR(IF(V20=0,T20,IFERROR(VALUE(TRIM(MID(SUBSTITUTE(K20,"-",REPT(" ",100)),(U20-V20-1)*100+1,100))),"")),"") | X20: =IFERROR(RealTime_Prediction!B4,"") -> ⚠ No confident prediction | Y20: =IF(AND(X20<>"",L20<>""),IF(X20=L20,"✓ YES","✗ NO"),"")
E21: =FALSE() -> FALSE | F21: =FALSE() -> FALSE | G21: =FALSE() -> FALSE | H21: =FALSE() -> FALSE | I21: =FALSE() -> FALSE | J21: =FALSE() -> FALSE | M21: =IFERROR(VALUE(TRIM(MID(SUBSTITUTE(K21,"-",REPT(" ",100)),(1-1)*100+1,100))),"") | N21: =IFERROR(VALUE(TRIM(MID(SUBSTITUTE(K21,"-",REPT(" ",100)),(2-1)*100+1,100))),"") | O21: =IFERROR(VALUE(TRIM(MID(SUBSTITUTE(K21,"-",REPT(" ",100)),(3-1)*100+1,100))),"") | P21: =IFERROR(VALUE(TRIM(MID(SUBSTITUTE(K21,"-",REPT(" ",100)),(4-1)*100+1,100))),"") | Q21: =IFERROR(VALUE(TRIM(MID(SUBSTITUTE(K21,"-",REPT(" ",100)),(5-1)*100+1,100))),"") | R21: =IFERROR(VALUE(TRIM(MID(SUBSTITUTE(K21,"-",REPT(" ",100)),(6-1)*100+1,100))),"") | S21: =IFERROR(VALUE(TRIM(MID(SUBSTITUTE(K21,"-",REPT(" ",100)),(7-1)*100+1,100))),"") | T21: =IFERROR(LOOKUP(2,1/(M21:S21<>""),M21:S21),"") | U21: =IF(K21="","",LEN(K21)-LEN(SUBSTITUTE(K21,"-",""))+1) | V21: 0 | W21: =IFERROR(IF(V21=0,T21,IFERROR(VALUE(TRIM(MID(SUBSTITUTE(K21,"-",REPT(" ",100)),(U21-V21-1)*100+1,100))),"")),"") | X21: =IFERROR(RealTime_Prediction!B4,"") -> ⚠ No confident prediction | Y21: =IF(AND(X21<>"",L21<>""),IF(X21=L21,"✓ YES","✗ NO"),"")
E22: =FALSE() -> FALSE | F22: =FALSE() -> FALSE | G22: =FALSE() -> FALSE | H22: =FALSE() -> FALSE | I22: =FALSE() -> FALSE | J22: =FALSE() -> FALSE | M22: =IFERROR(VALUE(TRIM(MID(SUBSTITUTE(K22,"-",REPT(" ",100)),(1-1)*100+1,100))),"") | N22: =IFERROR(VALUE(TRIM(MID(SUBSTITUTE(K22,"-",REPT(" ",100)),(2-1)*100+1,100))),"") | O22: =IFERROR(VALUE(TRIM(MID(SUBSTITUTE(K22,"-",REPT(" ",100)),(3-1)*100+1,100))),"") | P22: =IFERROR(VALUE(TRIM(MID(SUBSTITUTE(K22,"-",REPT(" ",100)),(4-1)*100+1,100))),"") | Q22: =IFERROR(VALUE(TRIM(MID(SUBSTITUTE(K22,"-",REPT(" ",100)),(5-1)*100+1,100))),"") | R22: =IFERROR(VALUE(TRIM(MID(SUBSTITUTE(K22,"-",REPT(" ",100)),(6-1)*100+1,100))),"") | S22: =IFERROR(VALUE(TRIM(MID(SUBSTITUTE(K22,"-",REPT(" ",100)),(7-1)*100+1,100))),"") | T22: =IFERROR(LOOKUP(2,1/(M22:S22<>""),M22:S22),"") | U22: =IF(K22="","",LEN(K22)-LEN(SUBSTITUTE(K22,"-",""))+1) | V22: 0 | W22: =IFERROR(IF(V22=0,T22,IFERROR(VALUE(TRIM(MID(SUBSTITUTE(K22,"-",REPT(" ",100)),(U22-V22-1)*100+1,100))),"")),"") | X22: =IFERROR(RealTime_Prediction!B4,"") -> ⚠ No confident prediction | Y22: =IF(AND(X22<>"",L22<>""),IF(X22=L22,"✓ YES","✗ NO"),"")
E23: =FALSE() -> FALSE | F23: =FALSE() -> FALSE | G23: =FALSE() -> FALSE | H23: =FALSE() -> FALSE | I23: =FALSE() -> FALSE | J23: =FALSE() -> FALSE | M23: =IFERROR(VALUE(TRIM(MID(SUBSTITUTE(K23,"-",REPT(" ",100)),(1-1)*100+1,100))),"") | N23: =IFERROR(VALUE(TRIM(MID(SUBSTITUTE(K23,"-",REPT(" ",100)),(2-1)*100+1,100))),"") | O23: =IFERROR(VALUE(TRIM(MID(SUBSTITUTE(K23,"-",REPT(" ",100)),(3-1)*100+1,100))),"") | P23: =IFERROR(VALUE(TRIM(MID(SUBSTITUTE(K23,"-",REPT(" ",100)),(4-1)*100+1,100))),"") | Q23: =IFERROR(VALUE(TRIM(MID(SUBSTITUTE(K23,"-",REPT(" ",100)),(5-1)*100+1,100))),"") | R23: =IFERROR(VALUE(TRIM(MID(SUBSTITUTE(K23,"-",REPT(" ",100)),(6-1)*100+1,100))),"") | S23: =IFERROR(VALUE(TRIM(MID(SUBSTITUTE(K23,"-",REPT(" ",100)),(7-1)*100+1,100))),"") | T23: =IFERROR(LOOKUP(2,1/(M23:S23<>""),M23:S23),"") | U23: =IF(K23="","",LEN(K23)-LEN(SUBSTITUTE(K23,"-",""))+1) | V23: 0 | W23: =IFERROR(IF(V23=0,T23,IFERROR(VALUE(TRIM(MID(SUBSTITUTE(K23,"-",REPT(" ",100)),(U23-V23-1)*100+1,100))),"")),"") | X23: =IFERROR(RealTime_Prediction!B4,"") -> ⚠ No confident prediction | Y23: =IF(AND(X23<>"",L23<>""),IF(X23=L23,"✓ YES","✗ NO"),"")
E24: =FALSE() -> FALSE | F24: =FALSE() -> FALSE | G24: =FALSE() -> FALSE | H24: =FALSE() -> FALSE | I24: =FALSE() -> FALSE | J24: =FALSE() -> FALSE | M24: =IFERROR(VALUE(TRIM(MID(SUBSTITUTE(K24,"-",REPT(" ",100)),(1-1)*100+1,100))),"") | N24: =IFERROR(VALUE(TRIM(MID(SUBSTITUTE(K24,"-",REPT(" ",100)),(2-1)*100+1,100))),"") | O24: =IFERROR(VALUE(TRIM(MID(SUBSTITUTE(K24,"-",REPT(" ",100)),(3-1)*100+1,100))),"") | P24: =IFERROR(VALUE(TRIM(MID(SUBSTITUTE(K24,"-",REPT(" ",100)),(4-1)*100+1,100))),"") | Q24: =IFERROR(VALUE(TRIM(MID(SUBSTITUTE(K24,"-",REPT(" ",100)),(5-1)*100+1,100))),"") | R24: =IFERROR(VALUE(TRIM(MID(SUBSTITUTE(K24,"-",REPT(" ",100)),(6-1)*100+1,100))),"") | S24: =IFERROR(VALUE(TRIM(MID(SUBSTITUTE(K24,"-",REPT(" ",100)),(7-1)*100+1,100))),"") | T24: =IFERROR(LOOKUP(2,1/(M24:S24<>""),M24:S24),"") | U24: =IF(K24="","",LEN(K24)-LEN(SUBSTITUTE(K24,"-",""))+1) | V24: 0 | W24: =IFERROR(IF(V24=0,T24,IFERROR(VALUE(TRIM(MID(SUBSTITUTE(K24,"-",REPT(" ",100)),(U24-V24-1)*100+1,100))),"")),"") | X24: =IFERROR(RealTime_Prediction!B4,"") -> ⚠ No confident prediction | Y24: =IF(AND(X24<>"",L24<>""),IF(X24=L24,"✓ YES","✗ NO"),"")
E25: =FALSE() -> FALSE | F25: =FALSE() -> FALSE | G25: =FALSE() -> FALSE | H25: =FALSE() -> FALSE | I25: =FALSE() -> FALSE | J25: =FALSE() -> FALSE | M25: =IFERROR(VALUE(TRIM(MID(SUBSTITUTE(K25,"-",REPT(" ",100)),(1-1)*100+1,100))),"") | N25: =IFERROR(VALUE(TRIM(MID(SUBSTITUTE(K25,"-",REPT(" ",100)),(2-1)*100+1,100))),"") | O25: =IFERROR(VALUE(TRIM(MID(SUBSTITUTE(K25,"-",REPT(" ",100)),(3-1)*100+1,100))),"") | P25: =IFERROR(VALUE(TRIM(MID(SUBSTITUTE(K25,"-",REPT(" ",100)),(4-1)*100+1,100))),"") | Q25: =IFERROR(VALUE(TRIM(MID(SUBSTITUTE(K25,"-",REPT(" ",100)),(5-1)*100+1,100))),"") | R25: =IFERROR(VALUE(TRIM(MID(SUBSTITUTE(K25,"-",REPT(" ",100)),(6-1)*100+1,100))),"") | S25: =IFERROR(VALUE(TRIM(MID(SUBSTITUTE(K25,"-",REPT(" ",100)),(7-1)*100+1,100))),"") | T25: =IFERROR(LOOKUP(2,1/(M25:S25<>""),M25:S25),"") | U25: =IF(K25="","",LEN(K25)-LEN(SUBSTITUTE(K25,"-",""))+1) | V25: 0 | W25: =IFERROR(IF(V25=0,T25,IFERROR(VALUE(TRIM(MID(SUBSTITUTE(K25,"-",REPT(" ",100)),(U25-V25-1)*100+1,100))),"")),"") | X25: =IFERROR(RealTime_Prediction!B4,"") -> ⚠ No confident prediction | Y25: =IF(AND(X25<>"",L25<>""),IF(X25=L25,"✓ YES","✗ NO"),"")
E26: =FALSE() -> FALSE | F26: =FALSE() -> FALSE | G26: =FALSE() -> FALSE | H26: =FALSE() -> FALSE | I26: =FALSE() -> FALSE | J26: =FALSE() -> FALSE | M26: =IFERROR(VALUE(TRIM(MID(SUBSTITUTE(K26,"-",REPT(" ",100)),(1-1)*100+1,100))),"") | N26: =IFERROR(VALUE(TRIM(MID(SUBSTITUTE(K26,"-",REPT(" ",100)),(2-1)*100+1,100))),"") | O26: =IFERROR(VALUE(TRIM(MID(SUBSTITUTE(K26,"-",REPT(" ",100)),(3-1)*100+1,100))),"") | P26: =IFERROR(VALUE(TRIM(MID(SUBSTITUTE(K26,"-",REPT(" ",100)),(4-1)*100+1,100))),"") | Q26: =IFERROR(VALUE(TRIM(MID(SUBSTITUTE(K26,"-",REPT(" ",100)),(5-1)*100+1,100))),"") | R26: =IFERROR(VALUE(TRIM(MID(SUBSTITUTE(K26,"-",REPT(" ",100)),(6-1)*100+1,100))),"") | S26: =IFERROR(VALUE(TRIM(MID(SUBSTITUTE(K26,"-",REPT(" ",100)),(7-1)*100+1,100))),"") | T26: =IFERROR(LOOKUP(2,1/(M26:S26<>""),M26:S26),"") | U26: =IF(K26="","",LEN(K26)-LEN(SUBSTITUTE(K26,"-",""))+1) | V26: 0 | W26: =IFERROR(IF(V26=0,T26,IFERROR(VALUE(TRIM(MID(SUBSTITUTE(K26,"-",REPT(" ",100)),(U26-V26-1)*100+1,100))),"")),"") | X26: =IFERROR(RealTime_Prediction!B4,"") -> ⚠ No confident prediction | Y26: =IF(AND(X26<>"",L26<>""),IF(X26=L26,"✓ YES","✗ NO"),"")
E27: =FALSE() -> FALSE | F27: =FALSE() -> FALSE | G27: =FALSE() -> FALSE | H27: =FALSE() -> FALSE | I27: =FALSE() -> FALSE | J27: =FALSE() -> FALSE | M27: =IFERROR(VALUE(TRIM(MID(SUBSTITUTE(K27,"-",REPT(" ",100)),(1-1)*100+1,100))),"") | N27: =IFERROR(VALUE(TRIM(MID(SUBSTITUTE(K27,"-",REPT(" ",100)),(2-1)*100+1,100))),"") | O27: =IFERROR(VALUE(TRIM(MID(SUBSTITUTE(K27,"-",REPT(" ",100)),(3-1)*100+1,100))),"") | P27: =IFERROR(VALUE(TRIM(MID(SUBSTITUTE(K27,"-",REPT(" ",100)),(4-1)*100+1,100))),"") | Q27: =IFERROR(VALUE(TRIM(MID(SUBSTITUTE(K27,"-",REPT(" ",100)),(5-1)*100+1,100))),"") | R27: =IFERROR(VALUE(TRIM(MID(SUBSTITUTE(K27,"-",REPT(" ",100)),(6-1)*100+1,100))),"") | S27: =IFERROR(VALUE(TRIM(MID(SUBSTITUTE(K27,"-",REPT(" ",100)),(7-1)*100+1,100))),"") | T27: =IFERROR(LOOKUP(2,1/(M27:S27<>""),M27:S27),"") | U27: =IF(K27="","",LEN(K27)-LEN(SUBSTITUTE(K27,"-",""))+1) | V27: 0 | W27: =IFERROR(IF(V27=0,T27,IFERROR(VALUE(TRIM(MID(SUBSTITUTE(K27,"-",REPT(" ",100)),(U27-V27-1)*100+1,100))),"")),"") | X27: =IFERROR(RealTime_Prediction!B4,"") -> ⚠ No confident prediction | Y27: =IF(AND(X27<>"",L27<>""),IF(X27=L27,"✓ YES","✗ NO"),"")
E28: =FALSE() -> FALSE | F28: =FALSE() -> FALSE | G28: =FALSE() -> FALSE | H28: =FALSE() -> FALSE | I28: =FALSE() -> FALSE | J28: =FALSE() -> FALSE | M28: =IFERROR(VALUE(TRIM(MID(SUBSTITUTE(K28,"-",REPT(" ",100)),(1-1)*100+1,100))),"") | N28: =IFERROR(VALUE(TRIM(MID(SUBSTITUTE(K28,"-",REPT(" ",100)),(2-1)*100+1,100))),"") | O28: =IFERROR(VALUE(TRIM(MID(SUBSTITUTE(K28,"-",REPT(" ",100)),(3-1)*100+1,100))),"") | P28: =IFERROR(VALUE(TRIM(MID(SUBSTITUTE(K28,"-",REPT(" ",100)),(4-1)*100+1,100))),"") | Q28: =IFERROR(VALUE(TRIM(MID(SUBSTITUTE(K28,"-",REPT(" ",100)),(5-1)*100+1,100))),"") | R28: =IFERROR(VALUE(TRIM(MID(SUBSTITUTE(K28,"-",REPT(" ",100)),(6-1)*100+1,100))),"") | S28: =IFERROR(VALUE(TRIM(MID(SUBSTITUTE(K28,"-",REPT(" ",100)),(7-1)*100+1,100))),"") | T28: =IFERROR(LOOKUP(2,1/(M28:S28<>""),M28:S28),"") | U28: =IF(K28="","",LEN(K28)-LEN(SUBSTITUTE(K28,"-",""))+1) | V28: 0 | W28: =IFERROR(IF(V28=0,T28,IFERROR(VALUE(TRIM(MID(SUBSTITUTE(K28,"-",REPT(" ",100)),(U28-V28-1)*100+1,100))),"")),"") | X28: =IFERROR(RealTime_Prediction!B4,"") -> ⚠ No confident prediction | Y28: =IF(AND(X28<>"",L28<>""),IF(X28=L28,"✓ YES","✗ NO"),"")
E29: =FALSE() -> FALSE | F29: =FALSE() -> FALSE | G29: =FALSE() -> FALSE | H29: =FALSE() -> FALSE | I29: =FALSE() -> FALSE | J29: =FALSE() -> FALSE | M29: =IFERROR(VALUE(TRIM(MID(SUBSTITUTE(K29,"-",REPT(" ",100)),(1-1)*100+1,100))),"") | N29: =IFERROR(VALUE(TRIM(MID(SUBSTITUTE(K29,"-",REPT(" ",100)),(2-1)*100+1,100))),"") | O29: =IFERROR(VALUE(TRIM(MID(SUBSTITUTE(K29,"-",REPT(" ",100)),(3-1)*100+1,100))),"") | P29: =IFERROR(VALUE(TRIM(MID(SUBSTITUTE(K29,"-",REPT(" ",100)),(4-1)*100+1,100))),"") | Q29: =IFERROR(VALUE(TRIM(MID(SUBSTITUTE(K29,"-",REPT(" ",100)),(5-1)*100+1,100))),"") | R29: =IFERROR(VALUE(TRIM(MID(SUBSTITUTE(K29,"-",REPT(" ",100)),(6-1)*100+1,100))),"") | S29: =IFERROR(VALUE(TRIM(MID(SUBSTITUTE(K29,"-",REPT(" ",100)),(7-1)*100+1,100))),"") | T29: =IFERROR(LOOKUP(2,1/(M29:S29<>""),M29:S29),"") | U29: =IF(K29="","",LEN(K29)-LEN(SUBSTITUTE(K29,"-",""))+1) | V29: 0 | W29: =IFERROR(IF(V29=0,T29,IFERROR(VALUE(TRIM(MID(SUBSTITUTE(K29,"-",REPT(" ",100)),(U29-V29-1)*100+1,100))),"")),"") | X29: =IFERROR(RealTime_Prediction!B4,"") -> ⚠ No confident prediction | Y29: =IF(AND(X29<>"",L29<>""),IF(X29=L29,"✓ YES","✗ NO"),"")
E30: =FALSE() -> FALSE | F30: =FALSE() -> FALSE | G30: =FALSE() -> FALSE | H30: =FALSE() -> FALSE | I30: =FALSE() -> FALSE | J30: =FALSE() -> FALSE | M30: =IFERROR(VALUE(TRIM(MID(SUBSTITUTE(K30,"-",REPT(" ",100)),(1-1)*100+1,100))),"") | N30: =IFERROR(VALUE(TRIM(MID(SUBSTITUTE(K30,"-",REPT(" ",100)),(2-1)*100+1,100))),"") | O30: =IFERROR(VALUE(TRIM(MID(SUBSTITUTE(K30,"-",REPT(" ",100)),(3-1)*100+1,100))),"") | P30: =IFERROR(VALUE(TRIM(MID(SUBSTITUTE(K30,"-",REPT(" ",100)),(4-1)*100+1,100))),"") | Q30: =IFERROR(VALUE(TRIM(MID(SUBSTITUTE(K30,"-",REPT(" ",100)),(5-1)*100+1,100))),"") | R30: =IFERROR(VALUE(TRIM(MID(SUBSTITUTE(K30,"-",REPT(" ",100)),(6-1)*100+1,100))),"") | S30: =IFERROR(VALUE(TRIM(MID(SUBSTITUTE(K30,"-",REPT(" ",100)),(7-1)*100+1,100))),"") | T30: =IFERROR(LOOKUP(2,1/(M30:S30<>""),M30:S30),"") | U30: =IF(K30="","",LEN(K30)-LEN(SUBSTITUTE(K30,"-",""))+1) | V30: 0 | W30: =IFERROR(IF(V30=0,T30,IFERROR(VALUE(TRIM(MID(SUBSTITUTE(K30,"-",REPT(" ",100)),(U30-V30-1)*100+1,100))),"")),"") | X30: =IFERROR(RealTime_Prediction!B4,"") -> ⚠ No confident prediction | Y30: =IF(AND(X30<>"",L30<>""),IF(X30=L30,"✓ YES","✗ NO"),"")
E31: =FALSE() -> FALSE | F31: =FALSE() -> FALSE | G31: =FALSE() -> FALSE | H31: =FALSE() -> FALSE | I31: =FALSE() -> FALSE | J31: =FALSE() -> FALSE | M31: =IFERROR(VALUE(TRIM(MID(SUBSTITUTE(K31,"-",REPT(" ",100)),(1-1)*100+1,100))),"") | N31: =IFERROR(VALUE(TRIM(MID(SUBSTITUTE(K31,"-",REPT(" ",100)),(2-1)*100+1,100))),"") | O31: =IFERROR(VALUE(TRIM(MID(SUBSTITUTE(K31,"-",REPT(" ",100)),(3-1)*100+1,100))),"") | P31: =IFERROR(VALUE(TRIM(MID(SUBSTITUTE(K31,"-",REPT(" ",100)),(4-1)*100+1,100))),"") | Q31: =IFERROR(VALUE(TRIM(MID(SUBSTITUTE(K31,"-",REPT(" ",100)),(5-1)*100+1,100))),"") | R31: =IFERROR(VALUE(TRIM(MID(SUBSTITUTE(K31,"-",REPT(" ",100)),(6-1)*100+1,100))),"") | S31: =IFERROR(VALUE(TRIM(MID(SUBSTITUTE(K31,"-",REPT(" ",100)),(7-1)*100+1,100))),"") | T31: =IFERROR(LOOKUP(2,1/(M31:S31<>""),M31:S31),"") | U31: =IF(K31="","",LEN(K31)-LEN(SUBSTITUTE(K31,"-",""))+1) | V31: 0 | W31: =IFERROR(IF(V31=0,T31,IFERROR(VALUE(TRIM(MID(SUBSTITUTE(K31,"-",REPT(" ",100)),(U31-V31-1)*100+1,100))),"")),"") | X31: =IFERROR(RealTime_Prediction!B4,"") -> ⚠ No confident prediction | Y31: =IF(AND(X31<>"",L31<>""),IF(X31=L31,"✓ YES","✗ NO"),"")
E32: =FALSE() -> FALSE | F32: =FALSE() -> FALSE | G32: =FALSE() -> FALSE | H32: =FALSE() -> FALSE | I32: =FALSE() -> FALSE | J32: =FALSE() -> FALSE | M32: =IFERROR(VALUE(TRIM(MID(SUBSTITUTE(K32,"-",REPT(" ",100)),(1-1)*100+1,100))),"") | N32: =IFERROR(VALUE(TRIM(MID(SUBSTITUTE(K32,"-",REPT(" ",100)),(2-1)*100+1,100))),"") | O32: =IFERROR(VALUE(TRIM(MID(SUBSTITUTE(K32,"-",REPT(" ",100)),(3-1)*100+1,100))),"") | P32: =IFERROR(VALUE(TRIM(MID(SUBSTITUTE(K32,"-",REPT(" ",100)),(4-1)*100+1,100))),"") | Q32: =IFERROR(VALUE(TRIM(MID(SUBSTITUTE(K32,"-",REPT(" ",100)),(5-1)*100+1,100))),"") | R32: =IFERROR(VALUE(TRIM(MID(SUBSTITUTE(K32,"-",REPT(" ",100)),(6-1)*100+1,100))),"") | S32: =IFERROR(VALUE(TRIM(MID(SUBSTITUTE(K32,"-",REPT(" ",100)),(7-1)*100+1,100))),"") | T32: =IFERROR(LOOKUP(2,1/(M32:S32<>""),M32:S32),"") | U32: =IF(K32="","",LEN(K32)-LEN(SUBSTITUTE(K32,"-",""))+1) | V32: 0 | W32: =IFERROR(IF(V32=0,T32,IFERROR(VALUE(TRIM(MID(SUBSTITUTE(K32,"-",REPT(" ",100)),(U32-V32-1)*100+1,100))),"")),"") | X32: =IFERROR(RealTime_Prediction!B4,"") -> ⚠ No confident prediction | Y32: =IF(AND(X32<>"",L32<>""),IF(X32=L32,"✓ YES","✗ NO"),"")
E33: =FALSE() -> FALSE | F33: =FALSE() -> FALSE | G33: =FALSE() -> FALSE | H33: =FALSE() -> FALSE | I33: =FALSE() -> FALSE | J33: =FALSE() -> FALSE | M33: =IFERROR(VALUE(TRIM(MID(SUBSTITUTE(K33,"-",REPT(" ",100)),(1-1)*100+1,100))),"") | N33: =IFERROR(VALUE(TRIM(MID(SUBSTITUTE(K33,"-",REPT(" ",100)),(2-1)*100+1,100))),"") | O33: =IFERROR(VALUE(TRIM(MID(SUBSTITUTE(K33,"-",REPT(" ",100)),(3-1)*100+1,100))),"") | P33: =IFERROR(VALUE(TRIM(MID(SUBSTITUTE(K33,"-",REPT(" ",100)),(4-1)*100+1,100))),"") | Q33: =IFERROR(VALUE(TRIM(MID(SUBSTITUTE(K33,"-",REPT(" ",100)),(5-1)*100+1,100))),"") | R33: =IFERROR(VALUE(TRIM(MID(SUBSTITUTE(K33,"-",REPT(" ",100)),(6-1)*100+1,100))),"") | S33: =IFERROR(VALUE(TRIM(MID(SUBSTITUTE(K33,"-",REPT(" ",100)),(7-1)*100+1,100))),"") | T33: =IFERROR(LOOKUP(2,1/(M33:S33<>""),M33:S33),"") | U33: =IF(K33="","",LEN(K33)-LEN(SUBSTITUTE(K33,"-",""))+1) | V33: 0 | W33: =IFERROR(IF(V33=0,T33,IFERROR(VALUE(TRIM(MID(SUBSTITUTE(K33,"-",REPT(" ",100)),(U33-V33-1)*100+1,100))),"")),"") | X33: =IFERROR(RealTime_Prediction!B4,"") -> ⚠ No confident prediction | Y33: =IF(AND(X33<>"",L33<>""),IF(X33=L33,"✓ YES","✗ NO"),"")
E34: =FALSE() -> FALSE | F34: =FALSE() -> FALSE | G34: =FALSE() -> FALSE | H34: =FALSE() -> FALSE | I34: =FALSE() -> FALSE | J34: =FALSE() -> FALSE | M34: =IFERROR(VALUE(TRIM(MID(SUBSTITUTE(K34,"-",REPT(" ",100)),(1-1)*100+1,100))),"") | N34: =IFERROR(VALUE(TRIM(MID(SUBSTITUTE(K34,"-",REPT(" ",100)),(2-1)*100+1,100))),"") | O34: =IFERROR(VALUE(TRIM(MID(SUBSTITUTE(K34,"-",REPT(" ",100)),(3-1)*100+1,100))),"") | P34: =IFERROR(VALUE(TRIM(MID(SUBSTITUTE(K34,"-",REPT(" ",100)),(4-1)*100+1,100))),"") | Q34: =IFERROR(VALUE(TRIM(MID(SUBSTITUTE(K34,"-",REPT(" ",100)),(5-1)*100+1,100))),"") | R34: =IFERROR(VALUE(TRIM(MID(SUBSTITUTE(K34,"-",REPT(" ",100)),(6-1)*100+1,100))),"") | S34: =IFERROR(VALUE(TRIM(MID(SUBSTITUTE(K34,"-",REPT(" ",100)),(7-1)*100+1,100))),"") | T34: =IFERROR(LOOKUP(2,1/(M34:S34<>""),M34:S34),"") | U34: =IF(K34="","",LEN(K34)-LEN(SUBSTITUTE(K34,"-",""))+1) | V34: 0 | W34: =IFERROR(IF(V34=0,T34,IFERROR(VALUE(TRIM(MID(SUBSTITUTE(K34,"-",REPT(" ",100)),(U34-V34-1)*100+1,100))),"")),"") | X34: =IFERROR(RealTime_Prediction!B4,"") -> ⚠ No confident prediction | Y34: =IF(AND(X34<>"",L34<>""),IF(X34=L34,"✓ YES","✗ NO"),"")
E35: =FALSE() -> FALSE | F35: =FALSE() -> FALSE | G35: =FALSE() -> FALSE | H35: =FALSE() -> FALSE | I35: =FALSE() -> FALSE | J35: =FALSE() -> FALSE | M35: =IFERROR(VALUE(TRIM(MID(SUBSTITUTE(K35,"-",REPT(" ",100)),(1-1)*100+1,100))),"") | N35: =IFERROR(VALUE(TRIM(MID(SUBSTITUTE(K35,"-",REPT(" ",100)),(2-1)*100+1,100))),"") | O35: =IFERROR(VALUE(TRIM(MID(SUBSTITUTE(K35,"-",REPT(" ",100)),(3-1)*100+1,100))),"") | P35: =IFERROR(VALUE(TRIM(MID(SUBSTITUTE(K35,"-",REPT(" ",100)),(4-1)*100+1,100))),"") | Q35: =IFERROR(VALUE(TRIM(MID(SUBSTITUTE(K35,"-",REPT(" ",100)),(5-1)*100+1,100))),"") | R35: =IFERROR(VALUE(TRIM(MID(SUBSTITUTE(K35,"-",REPT(" ",100)),(6-1)*100+1,100))),"") | S35: =IFERROR(VALUE(TRIM(MID(SUBSTITUTE(K35,"-",REPT(" ",100)),(7-1)*100+1,100))),"") | T35: =IFERROR(LOOKUP(2,1/(M35:S35<>""),M35:S35),"") | U35: =IF(K35="","",LEN(K35)-LEN(SUBSTITUTE(K35,"-",""))+1) | V35: 0 | W35: =IFERROR(IF(V35=0,T35,IFERROR(VALUE(TRIM(MID(SUBSTITUTE(K35,"-",REPT(" ",100)),(U35-V35-1)*100+1,100))),"")),"") | X35: =IFERROR(RealTime_Prediction!B4,"") -> ⚠ No confident prediction | Y35: =IF(AND(X35<>"",L35<>""),IF(X35=L35,"✓ YES","✗ NO"),"")
E36: =FALSE() -> FALSE | F36: =FALSE() -> FALSE | G36: =FALSE() -> FALSE | H36: =FALSE() -> FALSE | I36: =FALSE() -> FALSE | J36: =FALSE() -> FALSE | M36: =IFERROR(VALUE(TRIM(MID(SUBSTITUTE(K36,"-",REPT(" ",100)),(1-1)*100+1,100))),"") | N36: =IFERROR(VALUE(TRIM(MID(SUBSTITUTE(K36,"-",REPT(" ",100)),(2-1)*100+1,100))),"") | O36: =IFERROR(VALUE(TRIM(MID(SUBSTITUTE(K36,"-",REPT(" ",100)),(3-1)*100+1,100))),"") | P36: =IFERROR(VALUE(TRIM(MID(SUBSTITUTE(K36,"-",REPT(" ",100)),(4-1)*100+1,100))),"") | Q36: =IFERROR(VALUE(TRIM(MID(SUBSTITUTE(K36,"-",REPT(" ",100)),(5-1)*100+1,100))),"") | R36: =IFERROR(VALUE(TRIM(MID(SUBSTITUTE(K36,"-",REPT(" ",100)),(6-1)*100+1,100))),"") | S36: =IFERROR(VALUE(TRIM(MID(SUBSTITUTE(K36,"-",REPT(" ",100)),(7-1)*100+1,100))),"") | T36: =IFERROR(LOOKUP(2,1/(M36:S36<>""),M36:S36),"") | U36: =IF(K36="","",LEN(K36)-LEN(SUBSTITUTE(K36,"-",""))+1) | V36: 0 | W36: =IFERROR(IF(V36=0,T36,IFERROR(VALUE(TRIM(MID(SUBSTITUTE(K36,"-",REPT(" ",100)),(U36-V36-1)*100+1,100))),"")),"") | X36: =IFERROR(RealTime_Prediction!B4,"") -> ⚠ No confident prediction | Y36: =IF(AND(X36<>"",L36<>""),IF(X36=L36,"✓ YES","✗ NO"),"")
E37: =FALSE() -> FALSE | F37: =FALSE() -> FALSE | G37: =FALSE() -> FALSE | H37: =FALSE() -> FALSE | I37: =FALSE() -> FALSE | J37: =FALSE() -> FALSE | M37: =IFERROR(VALUE(TRIM(MID(SUBSTITUTE(K37,"-",REPT(" ",100)),(1-1)*100+1,100))),"") | N37: =IFERROR(VALUE(TRIM(MID(SUBSTITUTE(K37,"-",REPT(" ",100)),(2-1)*100+1,100))),"") | O37: =IFERROR(VALUE(TRIM(MID(SUBSTITUTE(K37,"-",REPT(" ",100)),(3-1)*100+1,100))),"") | P37: =IFERROR(VALUE(TRIM(MID(SUBSTITUTE(K37,"-",REPT(" ",100)),(4-1)*100+1,100))),"") | Q37: =IFERROR(VALUE(TRIM(MID(SUBSTITUTE(K37,"-",REPT(" ",100)),(5-1)*100+1,100))),"") | R37: =IFERROR(VALUE(TRIM(MID(SUBSTITUTE(K37,"-",REPT(" ",100)),(6-1)*100+1,100))),"") | S37: =IFERROR(VALUE(TRIM(MID(SUBSTITUTE(K37,"-",REPT(" ",100)),(7-1)*100+1,100))),"") | T37: =IFERROR(LOOKUP(2,1/(M37:S37<>""),M37:S37),"") | U37: =IF(K37="","",LEN(K37)-LEN(SUBSTITUTE(K37,"-",""))+1) | V37: 0 | W37: =IFERROR(IF(V37=0,T37,IFERROR(VALUE(TRIM(MID(SUBSTITUTE(K37,"-",REPT(" ",100)),(U37-V37-1)*100+1,100))),"")),"") | X37: =IFERROR(RealTime_Prediction!B4,"") -> ⚠ No confident prediction | Y37: =IF(AND(X37<>"",L37<>""),IF(X37=L37,"✓ YES","✗ NO"),"")
E38: =FALSE() -> FALSE | F38: =FALSE() -> FALSE | G38: =FALSE() -> FALSE | H38: =FALSE() -> FALSE | I38: =FALSE() -> FALSE | J38: =FALSE() -> FALSE | M38: =IFERROR(VALUE(TRIM(MID(SUBSTITUTE(K38,"-",REPT(" ",100)),(1-1)*100+1,100))),"") | N38: =IFERROR(VALUE(TRIM(MID(SUBSTITUTE(K38,"-",REPT(" ",100)),(2-1)*100+1,100))),"") | O38: =IFERROR(VALUE(TRIM(MID(SUBSTITUTE(K38,"-",REPT(" ",100)),(3-1)*100+1,100))),"") | P38: =IFERROR(VALUE(TRIM(MID(SUBSTITUTE(K38,"-",REPT(" ",100)),(4-1)*100+1,100))),"") | Q38: =IFERROR(VALUE(TRIM(MID(SUBSTITUTE(K38,"-",REPT(" ",100)),(5-1)*100+1,100))),"") | R38: =IFERROR(VALUE(TRIM(MID(SUBSTITUTE(K38,"-",REPT(" ",100)),(6-1)*100+1,100))),"") | S38: =IFERROR(VALUE(TRIM(MID(SUBSTITUTE(K38,"-",REPT(" ",100)),(7-1)*100+1,100))),"") | T38: =IFERROR(LOOKUP(2,1/(M38:S38<>""),M38:S38),"") | U38: =IF(K38="","",LEN(K38)-LEN(SUBSTITUTE(K38,"-",""))+1) | V38: 0 | W38: =IFERROR(IF(V38=0,T38,IFERROR(VALUE(TRIM(MID(SUBSTITUTE(K38,"-",REPT(" ",100)),(U38-V38-1)*100+1,100))),"")),"") | X38: =IFERROR(RealTime_Prediction!B4,"") -> ⚠ No confident prediction | Y38: =IF(AND(X38<>"",L38<>""),IF(X38=L38,"✓ YES","✗ NO"),"")
E39: =FALSE() -> FALSE | F39: =FALSE() -> FALSE | G39: =FALSE() -> FALSE | H39: =FALSE() -> FALSE | I39: =FALSE() -> FALSE | J39: =FALSE() -> FALSE | M39: =IFERROR(VALUE(TRIM(MID(SUBSTITUTE(K39,"-",REPT(" ",100)),(1-1)*100+1,100))),"") | N39: =IFERROR(VALUE(TRIM(MID(SUBSTITUTE(K39,"-",REPT(" ",100)),(2-1)*100+1,100))),"") | O39: =IFERROR(VALUE(TRIM(MID(SUBSTITUTE(K39,"-",REPT(" ",100)),(3-1)*100+1,100))),"") | P39: =IFERROR(VALUE(TRIM(MID(SUBSTITUTE(K39,"-",REPT(" ",100)),(4-1)*100+1,100))),"") | Q39: =IFERROR(VALUE(TRIM(MID(SUBSTITUTE(K39,"-",REPT(" ",100)),(5-1)*100+1,100))),"") | R39: =IFERROR(VALUE(TRIM(MID(SUBSTITUTE(K39,"-",REPT(" ",100)),(6-1)*100+1,100))),"") | S39: =IFERROR(VALUE(TRIM(MID(SUBSTITUTE(K39,"-",REPT(" ",100)),(7-1)*100+1,100))),"") | T39: =IFERROR(LOOKUP(2,1/(M39:S39<>""),M39:S39),"") | U39: =IF(K39="","",LEN(K39)-LEN(SUBSTITUTE(K39,"-",""))+1) | V39: 0 | W39: =IFERROR(IF(V39=0,T39,IFERROR(VALUE(TRIM(MID(SUBSTITUTE(K39,"-",REPT(" ",100)),(U39-V39-1)*100+1,100))),"")),"") | X39: =IFERROR(RealTime_Prediction!B4,"") -> ⚠ No confident prediction | Y39: =IF(AND(X39<>"",L39<>""),IF(X39=L39,"✓ YES","✗ NO"),"")
E40: =FALSE() -> FALSE | F40: =FALSE() -> FALSE | G40: =FALSE() -> FALSE | H40: =FALSE() -> FALSE | I40: =FALSE() -> FALSE | J40: =FALSE() -> FALSE | M40: =IFERROR(VALUE(TRIM(MID(SUBSTITUTE(K40,"-",REPT(" ",100)),(1-1)*100+1,100))),"") | N40: =IFERROR(VALUE(TRIM(MID(SUBSTITUTE(K40,"-",REPT(" ",100)),(2-1)*100+1,100))),"") | O40: =IFERROR(VALUE(TRIM(MID(SUBSTITUTE(K40,"-",REPT(" ",100)),(3-1)*100+1,100))),"") | P40: =IFERROR(VALUE(TRIM(MID(SUBSTITUTE(K40,"-",REPT(" ",100)),(4-1)*100+1,100))),"") | Q40: =IFERROR(VALUE(TRIM(MID(SUBSTITUTE(K40,"-",REPT(" ",100)),(5-1)*100+1,100))),"") | R40: =IFERROR(VALUE(TRIM(MID(SUBSTITUTE(K40,"-",REPT(" ",100)),(6-1)*100+1,100))),"") | S40: =IFERROR(VALUE(TRIM(MID(SUBSTITUTE(K40,"-",REPT(" ",100)),(7-1)*100+1,100))),"") | T40: =IFERROR(LOOKUP(2,1/(M40:S40<>""),M40:S40),"") | U40: =IF(K40="","",LEN(K40)-LEN(SUBSTITUTE(K40,"-",""))+1) | V40: 0 | W40: =IFERROR(IF(V40=0,T40,IFERROR(VALUE(TRIM(MID(SUBSTITUTE(K40,"-",REPT(" ",100)),(U40-V40-1)*100+1,100))),"")),"") | X40: =IFERROR(RealTime_Prediction!B4,"") -> ⚠ No confident prediction | Y40: =IF(AND(X40<>"",L40<>""),IF(X40=L40,"✓ YES","✗ NO"),"")
...

Sheet Logic_Core
A1: 🔬 LOGIC CORE | Pattern Correlation Matrix
A2: Each theory is tested against actual pitch results. Confidence = (Correct Predictions / Observations with sufficient data). Min 5 obs required.
A3: THEORY | B3: CONDITION | C3: FILTER | D3: OBSERVATIONS | E3: CORRECT Fastball | F3: CORRECT Curveball | G3: CORRECT Slider | H3: CORRECT Changeup | I3: TOTAL CORRECT | J3: CONFIDENCE % | K3: HOT? | L3: NOTES
A4: 📌 SECTION 1: Fixed Position Theories
A5: Fixed Position: Sign 1 = Pitch | B5: The Sign 1 in sequence is always the pitch call | C5: No filter (all situations) | D5: =COUNTIFS(Live_Input!M3:M102,"<>"&"",Live_Input!L3:L102,"<>"&"") -> 0 | E5: =COUNTIFS(Live_Input!M3:M102,"<>"&"",Live_Input!L3:L102,"Fastball") -> 0 | F5: =COUNTIFS(Live_Input!M3:M102,"<>"&"",Live_Input!L3:L102,"Curveball") -> 0 | G5: =COUNTIFS(Live_Input!M3:M102,"<>"&"",Live_Input!L3:L102,"Slider") -> 0 | H5: =COUNTIFS(Live_Input!M3:M102,"<>"&"",Live_Input!L3:L102,"Changeup") -> 0 | I5: =SUM(E5:H5) -> 0 | J5: =IF(D5>=5,I5/D5,"") | K5: =IF(J5>=0.8,"🔥 HOT","—") -> 🔥 HOT
A6: Fixed Position: Sign 2 = Pitch | B6: The Sign 2 in sequence is always the pitch call | C6: No filter (all situations) | D6: =COUNTIFS(Live_Input!N3:N102,"<>"&"",Live_Input!L3:L102,"<>"&"") -> 0 | E6: =COUNTIFS(Live_Input!N3:N102,"<>"&"",Live_Input!L3:L102,"Fastball") -> 0 | F6: =COUNTIFS(Live_Input!N3:N102,"<>"&"",Live_Input!L3:L102,"Curveball") -> 0 | G6: =COUNTIFS(Live_Input!N3:N102,"<>"&"",Live_Input!L3:L102,"Slider") -> 0 | H6: =COUNTIFS(Live_Input!N3:N102,"<>"&"",Live_Input!L3:L102,"Changeup") -> 0 | I6: =SUM(E6:H6) -> 0 | J6: =IF(D6>=5,I6/D6,"") | K6: =IF(J6>=0.8,"🔥 HOT","—") -> 🔥 HOT
A7: Fixed Position: Sign 3 = Pitch | B7: The Sign 3 in sequence is always the pitch call | C7: No filter (all situations) | D7: =COUNTIFS(Live_Input!O3:O102,"<>"&"",Live_Input!L3:L102,"<>"&"") -> 0 | E7: =COUNTIFS(Live_Input!O3:O102,"<>"&"",Live_Input!L3:L102,"Fastball") -> 0 | F7: =COUNTIFS(Live_Input!O3:O102,"<>"&"",Live_Input!L3:L102,"Curveball") -> 0 | G7: =COUNTIFS(Live_Input!O3:O102,"<>"&"",Live_Input!L3:L102,"Slider") -> 0 | H7: =COUNTIFS(Live_Input!O3:O102,"<>"&"",Live_Input!L3:L102,"Changeup") -> 0 | I7: =SUM(E7:H7) -> 0 | J7: =IF(D7>=5,I7/D7,"") | K7: =IF(J7>=0.8,"🔥 HOT","—") -> 🔥 HOT
A8: 🔑 SECTION 2: Indicator System (Key Number)
A9: Indicator Key = 1 | B9: When indicator 1 appears anywhere in signs 1-4 | C9: Sign1-4 checked for indicator | D9: =COUNTIFS(Live_Input!M3:M102,1,Live_Input!L3:L102,"<>"&"")+COUNTIFS(Live_Input!N3:N102,1,Live_Input!L3:L102,"<>"&"")+COUNTIFS(Live_Input!O3:O102,1,Live_Input!L3:L102,"<>"&"")+COUNTIFS(Live_Input!P3:P102,1,Live_Input!L3:L102,"<>"&"") -> 0 | E9: =COUNTIFS(Live_Input!M3:M102,1,Live_Input!L3:L102,"Fastball")+COUNTIFS(Live_Input!N3:N102,1,Live_Input!L3:L102,"Fastball")+COUNTIFS(Live_Input!O3:O102,1,Live_Input!L3:L102,"Fastball")+COUNTIFS(Live_Input!P3:P102,1,Live_Input!L3:L102,"Fastball") -> 0 | F9: =COUNTIFS(Live_Input!M3:M102,1,Live_Input!L3:L102,"Curveball")+COUNTIFS(Live_Input!N3:N102,1,Live_Input!L3:L102,"Curveball")+COUNTIFS(Live_Input!O3:O102,1,Live_Input!L3:L102,"Curveball")+COUNTIFS(Live_Input!P3:P102,1,Live_Input!L3:L102,"Curveball") -> 0 | G9: =COUNTIFS(Live_Input!M3:M102,1,Live_Input!L3:L102,"Slider")+COUNTIFS(Live_Input!N3:N102,1,Live_Input!L3:L102,"Slider")+COUNTIFS(Live_Input!O3:O102,1,Live_Input!L3:L102,"Slider")+COUNTIFS(Live_Input!P3:P102,1,Live_Input!L3:L102,"Slider") -> 0 | H9: =COUNTIFS(Live_Input!M3:M102,1,Live_Input!L3:L102,"Changeup")+COUNTIFS(Live_Input!N3:N102,1,Live_Input!L3:L102,"Changeup")+COUNTIFS(Live_Input!O3:O102,1,Live_Input!L3:L102,"Changeup")+COUNTIFS(Live_Input!P3:P102,1,Live_Input!L3:L102,"Changeup") -> 0 | I9: =SUM(E9:H9) -> 0 | J9: =IF(D9>=5,I9/D9,"") | K9: =IF(J9>=0.8,"🔥 HOT","—") -> 🔥 HOT
A10: Indicator Key = 2 | B10: When indicator 2 appears anywhere in signs 1-4 | C10: Sign1-4 checked for indicator | D10: =COUNTIFS(Live_Input!M3:M102,2,Live_Input!L3:L102,"<>"&"")+COUNTIFS(Live_Input!N3:N102,2,Live_Input!L3:L102,"<>"&"")+COUNTIFS(Live_Input!O3:O102,2,Live_Input!L3:L102,"<>"&"")+COUNTIFS(Live_Input!P3:P102,2,Live_Input!L3:L102,"<>"&"") -> 0 | E10: =COUNTIFS(Live_Input!M3:M102,2,Live_Input!L3:L102,"Fastball")+COUNTIFS(Live_Input!N3:N102,2,Live_Input!L3:L102,"Fastball")+COUNTIFS(Live_Input!O3:O102,2,Live_Input!L3:L102,"Fastball")+COUNTIFS(Live_Input!P3:P102,2,Live_Input!L3:L102,"Fastball") -> 0 | F10: =COUNTIFS(Live_Input!M3:M102,2,Live_Input!L3:L102,"Curveball")+COUNTIFS(Live_Input!N3:N102,2,Live_Input!L3:L102,"Curveball")+COUNTIFS(Live_Input!O3:O102,2,Live_Input!L3:L102,"Curveball")+COUNTIFS(Live_Input!P3:P102,2,Live_Input!L3:L102,"Curveball") -> 0 | G10: =COUNTIFS(Live_Input!M3:M102,2,Live_Input!L3:L102,"Slider")+COUNTIFS(Live_Input!N3:N102,2,Live_Input!L3:L102,"Slider")+COUNTIFS(Live_Input!O3:O102,2,Live_Input!L3:L102,"Slider")+COUNTIFS(Live_Input!P3:P102,2,Live_Input!L3:L102,"Slider") -> 0 | H10: =COUNTIFS(Live_Input!M3:M102,2,Live_Input!L3:L102,"Changeup")+COUNTIFS(Live_Input!N3:N102,2,Live_Input!L3:L102,"Changeup")+COUNTIFS(Live_Input!O3:O102,2,Live_Input!L3:L102,"Changeup")+COUNTIFS(Live_Input!P3:P102,2,Live_Input!L3:L102,"Changeup") -> 0 | I10: =SUM(E10:H10) -> 0 | J10: =IF(D10>=5,I10/D10,"") | K10: =IF(J10>=0.8,"🔥 HOT","—") -> 🔥 HOT
A11: Indicator Key = 3 | B11: When indicator 3 appears anywhere in signs 1-4 | C11: Sign1-4 checked for indicator | D11: =COUNTIFS(Live_Input!M3:M102,3,Live_Input!L3:L102,"<>"&"")+COUNTIFS(Live_Input!N3:N102,3,Live_Input!L3:L102,"<>"&"")+COUNTIFS(Live_Input!O3:O102,3,Live_Input!L3:L102,"<>"&"")+COUNTIFS(Live_Input!P3:P102,3,Live_Input!L3:L102,"<>"&"") -> 0 | E11: =COUNTIFS(Live_Input!M3:M102,3,Live_Input!L3:L102,"Fastball")+COUNTIFS(Live_Input!N3:N102,3,Live_Input!L3:L102,"Fastball")+COUNTIFS(Live_Input!O3:O102,3,Live_Input!L3:L102,"Fastball")+COUNTIFS(Live_Input!P3:P102,3,Live_Input!L3:L102,"Fastball") -> 0 | F11: =COUNTIFS(Live_Input!M3:M102,3,Live_Input!L3:L102,"Curveball")+COUNTIFS(Live_Input!N3:N102,3,Live_Input!L3:L102,"Curveball")+COUNTIFS(Live_Input!O3:O102,3,Live_Input!L3:L102,"Curveball")+COUNTIFS(Live_Input!P3:P102,3,Live_Input!L3:L102,"Curveball") -> 0 | G11: =COUNTIFS(Live_Input!M3:M102,3,Live_Input!L3:L102,"Slider")+COUNTIFS(Live_Input!N3:N102,3,Live_Input!L3:L102,"Slider")+COUNTIFS(Live_Input!O3:O102,3,Live_Input!L3:L102,"Slider")+COUNTIFS(Live_Input!P3:P102,3,Live_Input!L3:L102,"Slider") -> 0 | H11: =COUNTIFS(Live_Input!M3:M102,3,Live_Input!L3:L102,"Changeup")+COUNTIFS(Live_Input!N3:N102,3,Live_Input!L3:L102,"Changeup")+COUNTIFS(Live_Input!O3:O102,3,Live_Input!L3:L102,"Changeup")+COUNTIFS(Live_Input!P3:P102,3,Live_Input!L3:L102,"Changeup") -> 0 | I11: =SUM(E11:H11) -> 0 | J11: =IF(D11>=5,I11/D11,"") | K11: =IF(J11>=0.8,"🔥 HOT","—") -> 🔥 HOT
A12: Indicator Key = 4 | B12: When indicator 4 appears anywhere in signs 1-4 | C12: Sign1-4 checked for indicator | D12: =COUNTIFS(Live_Input!M3:M102,4,Live_Input!L3:L102,"<>"&"")+COUNTIFS(Live_Input!N3:N102,4,Live_Input!L3:L102,"<>"&"")+COUNTIFS(Live_Input!O3:O102,4,Live_Input!L3:L102,"<>"&"")+COUNTIFS(Live_Input!P3:P102,4,Live_Input!L3:L102,"<>"&"") -> 0 | E12: =COUNTIFS(Live_Input!M3:M102,4,Live_Input!L3:L102,"Fastball")+COUNTIFS(Live_Input!N3:N102,4,Live_Input!L3:L102,"Fastball")+COUNTIFS(Live_Input!O3:O102,4,Live_Input!L3:L102,"Fastball")+COUNTIFS(Live_Input!P3:P102,4,Live_Input!L3:L102,"Fastball") -> 0 | F12: =COUNTIFS(Live_Input!M3:M102,4,Live_Input!L3:L102,"Curveball")+COUNTIFS(Live_Input!N3:N102,4,Live_Input!L3:L102,"Curveball")+COUNTIFS(Live_Input!O3:O102,4,Live_Input!L3:L102,"Curveball")+COUNTIFS(Live_Input!P3:P102,4,Live_Input!L3:L102,"Curveball") -> 0 | G12: =COUNTIFS(Live_Input!M3:M102,4,Live_Input!L3:L102,"Slider")+COUNTIFS(Live_Input!N3:N102,4,Live_Input!L3:L102,"Slider")+COUNTIFS(Live_Input!O3:O102,4,Live_Input!L3:L102,"Slider")+COUNTIFS(Live_Input!P3:P102,4,Live_Input!L3:L102,"Slider") -> 0 | H12: =COUNTIFS(Live_Input!M3:M102,4,Live_Input!L3:L102,"Changeup")+COUNTIFS(Live_Input!N3:N102,4,Live_Input!L3:L102,"Changeup")+COUNTIFS(Live_Input!O3:O102,4,Live_Input!L3:L102,"Changeup")+COUNTIFS(Live_Input!P3:P102,4,Live_Input!L3:L102,"Changeup") -> 0 | I12: =SUM(E12:H12) -> 0 | J12: =IF(D12>=5,I12/D12,"") | K12: =IF(J12>=0.8,"🔥 HOT","—") -> 🔥 HOT
A13: Indicator Key = 5 | B13: When indicator 5 appears anywhere in signs 1-4 | C13: Sign1-4 checked for indicator | D13: =COUNTIFS(Live_Input!M3:M102,5,Live_Input!L3:L102,"<>"&"")+COUNTIFS(Live_Input!N3:N102,5,Live_Input!L3:L102,"<>"&"")+COUNTIFS(Live_Input!O3:O102,5,Live_Input!L3:L102,"<>"&"")+COUNTIFS(Live_Input!P3:P102,5,Live_Input!L3:L102,"<>"&"") -> 0 | E13: =COUNTIFS(Live_Input!M3:M102,5,Live_Input!L3:L102,"Fastball")+COUNTIFS(Live_Input!N3:N102,5,Live_Input!L3:L102,"Fastball")+COUNTIFS(Live_Input!O3:O102,5,Live_Input!L3:L102,"Fastball")+COUNTIFS(Live_Input!P3:P102,5,Live_Input!L3:L102,"Fastball") -> 0 | F13: =COUNTIFS(Live_Input!M3:M102,5,Live_Input!L3:L102,"Curveball")+COUNTIFS(Live_Input!N3:N102,5,Live_Input!L3:L102,"Curveball")+COUNTIFS(Live_Input!O3:O102,5,Live_Input!L3:L102,"Curveball")+COUNTIFS(Live_Input!P3:P102,5,Live_Input!L3:L102,"Curveball") -> 0 | G13: =COUNTIFS(Live_Input!M3:M102,5,Live_Input!L3:L102,"Slider")+COUNTIFS(Live_Input!N3:N102,5,Live_Input!L3:L102,"Slider")+COUNTIFS(Live_Input!O3:O102,5,Live_Input!L3:L102,"Slider")+COUNTIFS(Live_Input!P3:P102,5,Live_Input!L3:L102,"Slider") -> 0 | H13: =COUNTIFS(Live_Input!M3:M102,5,Live_Input!L3:L102,"Changeup")+COUNTIFS(Live_Input!N3:N102,5,Live_Input!L3:L102,"Changeup")+COUNTIFS(Live_Input!O3:O102,5,Live_Input!L3:L102,"Changeup")+COUNTIFS(Live_Input!P3:P102,5,Live_Input!L3:L102,"Changeup") -> 0 | I13: =SUM(E13:H13) -> 0 | J13: =IF(D13>=5,I13/D13,"") | K13: =IF(J13>=0.8,"🔥 HOT","—") -> 🔥 HOT
A14: 🔄 SECTION 3: Inning Flip (ODD vs EVEN)
A15: Odd Innings: Sign 1 = Pitch | B15: In ODD innings, first sign is the call | C15: ODD inning only (MOD(Inning,2)=1) | D15: =SUMPRODUCT((MOD(Live_Input!A3:A102,2)=1)*(Live_Input!M3:M102<>"")*(Live_Input!L3:L102<>"")) -> 0 | E15: =SUMPRODUCT((MOD(Live_Input!A3:A102,2)=1)*(Live_Input!M3:M102<>"")*(Live_Input!L3:L102="Fastball")) -> 0 | F15: =SUMPRODUCT((MOD(Live_Input!A3:A102,2)=1)*(Live_Input!M3:M102<>"")*(Live_Input!L3:L102="Curveball")) -> 0 | G15: =SUMPRODUCT((MOD(Live_Input!A3:A102,2)=1)*(Live_Input!M3:M102<>"")*(Live_Input!L3:L102="Slider")) -> 0 | H15: =SUMPRODUCT((MOD(Live_Input!A3:A102,2)=1)*(Live_Input!M3:M102<>"")*(Live_Input!L3:L102="Changeup")) -> 0 | I15: =SUM(E15:H15) -> 0 | J15: =IF(D15>=5,I15/D15,"") | K15: =IF(J15>=0.8,"🔥 HOT","—") -> 🔥 HOT
A16: Even Innings: Sign 2 = Pitch | B16: In EVEN innings, second sign is the call | C16: EVEN inning only (MOD(Inning,2)=0) | D16: =SUMPRODUCT((MOD(Live_Input!A3:A102,2)=0)*(Live_Input!A3:A102>0)*(Live_Input!N3:N102<>"")*(Live_Input!L3:L102<>"")) -> 0 | E16: =SUMPRODUCT((MOD(Live_Input!A3:A102,2)=0)*(Live_Input!A3:A102>0)*(Live_Input!N3:N102<>"")*(Live_Input!L3:L102="Fastball")) -> 0 | F16: =SUMPRODUCT((MOD(Live_Input!A3:A102,2)=0)*(Live_Input!A3:A102>0)*(Live_Input!N3:N102<>"")*(Live_Input!L3:L102="Curveball")) -> 0 | G16: =SUMPRODUCT((MOD(Live_Input!A3:A102,2)=0)*(Live_Input!A3:A102>0)*(Live_Input!N3:N102<>"")*(Live_Input!L3:L102="Slider")) -> 0 | H16: =SUMPRODUCT((MOD(Live_Input!A3:A102,2)=0)*(Live_Input!A3:A102>0)*(Live_Input!N3:N102<>"")*(Live_Input!L3:L102="Changeup")) -> 0 | I16: =SUM(E16:H16) -> 0 | J16: =IF(D16>=5,I16/D16,"") | K16: =IF(J16>=0.8,"🔥 HOT","—") -> 🔥 HOT
A17: 🤲 SECTION 4: Tell-Based Flip (Touch Mask / Chest Wipe)
A18: Touch Mask → Sign 2 = Pitch | B18: When Touch Mask (G) is checked, Sign 2 is the call | C18: Touch Mask = TRUE | D18: =COUNTIFS(Live_Input!G3:G102,TRUE(),Live_Input!N3:N102,"<>"&"",Live_Input!L3:L102,"<>"&"") -> 0 | E18: =COUNTIFS(Live_Input!G3:G102,TRUE(),Live_Input!N3:N102,"<>"&"",Live_Input!L3:L102,"Fastball") -> 0 | F18: =COUNTIFS(Live_Input!G3:G102,TRUE(),Live_Input!N3:N102,"<>"&"",Live_Input!L3:L102,"Curveball") -> 0 | G18: =COUNTIFS(Live_Input!G3:G102,TRUE(),Live_Input!N3:N102,"<>"&"",Live_Input!L3:L102,"Slider") -> 0 | H18: =COUNTIFS(Live_Input!G3:G102,TRUE(),Live_Input!N3:N102,"<>"&"",Live_Input!L3:L102,"Changeup") -> 0 | I18: =SUM(E18:H18) -> 0 | J18: =IF(D18>=5,I18/D18,"") | K18: =IF(J18>=0.8,"🔥 HOT","—") -> 🔥 HOT
A19: Chest Wipe → Last Sign = Pitch | B19: When Chest Wipe (F) is checked, Last sign is the call | C19: Chest Wipe = TRUE | D19: =COUNTIFS(Live_Input!F3:F102,TRUE(),Live_Input!T3:T102,"<>"&"",Live_Input!L3:L102,"<>"&"") -> 0 | E19: =COUNTIFS(Live_Input!F3:F102,TRUE(),Live_Input!T3:T102,"<>"&"",Live_Input!L3:L102,"Fastball") -> 0 | F19: =COUNTIFS(Live_Input!F3:F102,TRUE(),Live_Input!T3:T102,"<>"&"",Live_Input!L3:L102,"Curveball") -> 0 | G19: =COUNTIFS(Live_Input!F3:F102,TRUE(),Live_Input!T3:T102,"<>"&"",Live_Input!L3:L102,"Slider") -> 0 | H19: =COUNTIFS(Live_Input!F3:F102,TRUE(),Live_Input!T3:T102,"<>"&"",Live_Input!L3:L102,"Changeup") -> 0 | I19: =SUM(E19:H19) -> 0 | J19: =IF(D19>=5,I19/D19,"") | K19: =IF(J19>=0.8,"🔥 HOT","—") -> 🔥 HOT
A20: 🏃 SECTION 5: Runner on 2nd (Simple vs Complex Signs)
A21: Simple Signs: Sign 1 = Pitch (No Runner) | B21: Runner on 2nd = FALSE → Sign 1 is the call | C21: R on 2nd = FALSE | D21: =COUNTIFS(Live_Input!E3:E102,FALSE(),Live_Input!M3:M102,"<>"&"",Live_Input!L3:L102,"<>"&"") -> 0 | E21: =COUNTIFS(Live_Input!E3:E102,FALSE(),Live_Input!M3:M102,"<>"&"",Live_Input!L3:L102,"Fastball") -> 0 | F21: =COUNTIFS(Live_Input!E3:E102,FALSE(),Live_Input!M3:M102,"<>"&"",Live_Input!L3:L102,"Curveball") -> 0 | G21: =COUNTIFS(Live_Input!E3:E102,FALSE(),Live_Input!M3:M102,"<>"&"",Live_Input!L3:L102,"Slider") -> 0 | H21: =COUNTIFS(Live_Input!E3:E102,FALSE(),Live_Input!M3:M102,"<>"&"",Live_Input!L3:L102,"Changeup") -> 0 | I21: =SUM(E21:H21) -> 0 | J21: =IF(D21>=5,I21/D21,"") | K21: =IF(J21>=0.8,"🔥 HOT","—") -> 🔥 HOT
A22: Complex Signs: Last Sign = Pitch (Runner On) | B22: Runner on 2nd = TRUE → Last sign is the call | C22: R on 2nd = TRUE | D22: =COUNTIFS(Live_Input!E3:E102,TRUE(),Live_Input!T3:T102,"<>"&"",Live_Input!L3:L102,"<>"&"") -> 0 | E22: =COUNTIFS(Live_Input!E3:E102,TRUE(),Live_Input!T3:T102,"<>"&"",Live_Input!L3:L102,"Fastball") -> 0 | F22: =COUNTIFS(Live_Input!E3:E102,TRUE(),Live_Input!T3:T102,"<>"&"",Live_Input!L3:L102,"Curveball") -> 0 | G22: =COUNTIFS(Live_Input!E3:E102,TRUE(),Live_Input!T3:T102,"<>"&"",Live_Input!L3:L102,"Slider") -> 0 | H22: =COUNTIFS(Live_Input!E3:E102,TRUE(),Live_Input!T3:T102,"<>"&"",Live_Input!L3:L102,"Changeup") -> 0 | I22: =SUM(E22:H22) -> 0 | J22: =IF(D22>=5,I22/D22,"") | K22: =IF(J22>=0.8,"🔥 HOT","—") -> 🔥 HOT
A23: Shake-Adjusted Sign = Pitch | B23: After applying shake offset, adjusted sign matches pitch | C23: Shake Count ≥ 1 | D23: =COUNTIFS(Live_Input!V3:V102,">="&1,Live_Input!W3:W102,"<>"&"",Live_Input!L3:L102,"<>"&"") -> 0 | E23: =COUNTIFS(Live_Input!V3:V102,">="&1,Live_Input!W3:W102,"<>"&"",Live_Input!L3:L102,"Fastball") -> 0 | F23: =COUNTIFS(Live_Input!V3:V102,">="&1,Live_Input!W3:W102,"<>"&"",Live_Input!L3:L102,"Curveball") -> 0 | G23: =COUNTIFS(Live_Input!V3:V102,">="&1,Live_Input!W3:W102,"<>"&"",Live_Input!L3:L102,"Slider") -> 0 | H23: =COUNTIFS(Live_Input!V3:V102,">="&1,Live_Input!W3:W102,"<>"&"",Live_Input!L3:L102,"Changeup") -> 0 | I23: =SUM(E23:H23) -> 0 | J23: =IF(D23>=5,I23/D23,"") | K23: =IF(J23>=0.8,"🔥 HOT","—") -> 🔥 HOT

Sheet RealTime_Prediction
A1: 🎯 SIGNAL-INTERCEPT | Real-Time Prediction Dashboard
A2: 🔮 NEXT PITCH GUESS
A3: Leading Theory: | B3: =IFERROR(INDEX(Logic_Core!A5:A30,MATCH(MAX(IF(Logic_Core!J5:J30>=0.8,Logic_Core!J5:J30)),IF(Logic_Core!J5:J30>=0.8,Logic_Core!J5:J30),0)),"No Hot Theory (Need 5+ Obs)") -> No Hot Theory (Need 5+ Obs)
A4: Predicted Pitch: | B4: =IFERROR(IF(MAX(Logic_Core!J5:J30)<0.8,"⚠ No confident prediction",_xludf.let(hot_row,MATCH(MAX(IF(Logic_Core!J5:J30>=0.8,Logic_Core!J5:J30)),Logic_Core!J5:J30,0),INDEX({"Fastball","Curveball","Slider","Changeup"},MATCH(MAX(OFFSET(Logic_Core!E5,hot_row-1,0,1,4)),OFFSET(Logic_Core!E5,hot_row-1,0,1,4),0)))),"Enter data first") -> ⚠ No confident prediction
A5: Confidence: | B5: =IFERROR(IF(MAX(Logic_Core!J5:J30)<0.5,"—",TEXT(MAX(Logic_Core!J5:J30),"0.0%")),"—") -> —
A7: 🚨 SCOUTING ALERTS
